Workbook

Sheet B2026
A1: K EURO | E1: 2025 | Q1: 2025 | R1: 2026 | S1: 2027
E2: Jan | F2: Fev | G2: Mar | H2: Avr | I2: Mai | J2: Jui | K2: Juil | L2: Aou | M2: Sep | N2: Oct | O2: Nov | P2: Dec | Q2: Cumul fin Décembre | R2: Cumul fin Décembre | S2: Cumul fin Décembre
A3: PRODUIT | B3: PLAN_COMPTE | C3: TERRITOIRE | D3: CONSTRUCTEUR | E3: Budget | F3: Budget | G3: Budget | H3: Budget | I3: Budget | J3: Budget | K3: Budget | L3: Budget | M3: Budget | N3: Budget | O3: Budget | P3: Budget | Q3: Budget | R3: Plan N+1 | S3: Plan N+2
A4: Lift trucks | B4: Chiffre d'affaires | C4: Cameroun | D4: KALMAR | E4: 0 | F4: 571.68381 | G4: 0 | H4: 0 | I4: 815.60224 | J4: 0 | K4: 0 | L4: 815.60224 | M4: 0 | N4: 243.91843 | O4: 571.68381 | P4: 0 | Q4: 3018.4905 | R4: 3590.1744 | S4: 3917.9397
A5: Lift trucks | B5: Quantités facturées | C5: Cameroun | D5: KALMAR | E5: 0 | F5: 1 | G5: 0 | H5: 0 | I5: 2 | J5: 0 | K5: 0 | L5: 2 | M5: 0 | N5: 1 | O5: 1 | P5: 0 | Q5: 7 | R5: 0 | S5: 0
A6: Lift trucks | B6: Chiffre d'affaires | C6: Cameroun | D6: MANITOU | E6: 345.36274 | F6: 321.45209 | G6: 558.34997 | H6: 393.34431 | I6: 362.79081 | J6: 278.4086 | K6: 129.83758 | L6: 154.73516 | M6: 355.15982 | N6: 342.42479 | O6: 304.1858 | P6: 341.32307 | Q6: 3887.3747 | R6: 8359.324 | S6: 9255.7739
A7: Lift trucks | B7: Quantités facturées | C7: Cameroun | D7: MANITOU | E7: 2 | F7: 4 | G7: 5 | H7: 3 | I7: 3 | J7: 4 | K7: 0 | L7: 1 | M7: 6 | N7: 3 | O7: 2 | P7: 6 | Q7: 39 | R7: 29 | S7: 28
A8: Agricole | B8: Chiffre d'affaires | C8: Cameroun | D8: MASSEY FERGUSON | E8: 0 | F8: 328.52763 | G8: 32.776539 | H8: 32.776539 | I8: 92.231655 | J8: 32.776539 | K8: 0 | L8: 32.776539 | M8: 0 | N8: 32.776539 | O8: 32.776539 | P8: 92.231655 | Q8: 709.65018 | R8: 610.55831 | S8: 768.34305
A9: Agricole | B9: Quantités facturées | C9: Cameroun | D9: MASSEY FERGUSON | E9: 0 | F9: 4 | G9: 1 | H9: 1 | I9: 2 | J9: 1 | K9: 0 | L9: 1 | M9: 0 | N9: 1 | O9: 1 | P9: 2 | Q9: 14 | R9: 17 | S9: 21
A10: Agricole | B10: Chiffre d'affaires | C10: Cameroun | D10: NARDI | E10: 36.587764 | F10: 36.587764 | G10: 54.881646 | H10: 36.587764 | I10: 36.587764 | J10: 54.881646 | K10: 36.587764 | L10: 54.881646 | M10: 54.881646 | N10: 54.881646 | O10: 36.587764 | P10: 54.881646 | Q10: 548.81646 | R10: 212.9869 | S10: 243.4136
A11: Agricole | B11: Quantités facturées | C11: Cameroun | D11: NARDI | E11: 2 | F11: 2 | G11: 3 | H11: 2 | I11: 2 | J11: 3 | K11: 2 | L11: 3 | M11: 3 | N11: 3 | O11: 2 | P11: 3 | Q11: 30 | R11: 35 | S11: 40
A12: Lift trucks | B12: Chiffre d'affaires | C12: Congo | D12: KALMAR | E12: 191.841 | F12: 0 | G12: 0 | H12: 0 | I12: 0 | J12: 0 | K12: 0 | L12: 0 | M12: 0 | N12: 0 | O12: 0 | P12: 191.841 | Q12: 383.68201 | R12: 383.68201 | S12: 959.20502
A13: Lift trucks | B13: Quantités facturées | C13: Congo | D13: KALMAR | E13: 1 | F13: 0 | G13: 0 | H13: 0 | I13: 0 | J13: 0 | K13: 0 | L13: 0 | M13: 0 | N13: 0 | O13: 0 | P13: 1 | Q13: 2 | R13: 2 | S13: 5
A14: Lift trucks | B14: Chiffre d'affaires | C14: Congo | D14: MANITOU | E14: 32.04961 | F14: 165.09126 | G14: 141.51372 | H14: 34.260348 | I14: 55.43457 | J14: 34.260348 | K14: 34.260348 | L14: 87.48418 | M14: 32.04961 | N14: 70.756862 | O14: 130.35157 | P14: 32.04961 | Q14: 849.56204 | R14: 1411.0306 | S14: 1264.8774
A15: Lift trucks | B15: Quantités facturées | C15: Congo | D15: MANITOU | E15: 1 | F15: 2 | G15: 2 | H15: 1 | I15: 1 | J15: 1 | K15: 1 | L15: 2 | M15: 1 | N15: 1 | O15: 1 | P15: 1 | Q15: 15 | R15: 17 | S15: 16
... A95: Agricole | B95: Quantités facturées | C95: Total Territoire | D95: NARDI | E95: 10 | F95: 14 | G95: 18 | H95: 20 | I95: 18 | J95: 19 | K95: 18 | L95: 19 | M95: 18 | N95: 14 | O95: 16 | P95: 21 | Q95: 205 | R95: 251 | S95: 263

Sheet DRAFT - KPI's MANUTENTION ET AG
A1: PAYS | B1: YTD vs B2025 | E1: 45658 | H1: 45689 | K1: 45717 | N1: 45748 | Q1: 45778 | T1: 45809 | W1: 45839 | Z1: 45870 | AC1: 45901 | AF1: 45931 | AI1: 45962 | AL1: 45992
B2: Objectif | C2: Réalisé | D2: % | E2: Objectif | F2: Réalisé | G2: % | H2: Objectif | I2: Réalisé | J2: % | K2: Objectif | L2: Réalisé | M2: % | N2: Objectif | O2: Réalisé | P2: % | Q2: Objectif | R2: Réalisé | S2: % | T2: Objectif | U2: Réalisé | V2: % | W2: Objectif | X2: Réalisé | Y2: % | Z2: Objectif | AA2: Réalisé | AB2: % | AC2: Objectif | AD2: Réalisé | AE2: % | AF2: Objectif | AG2: Réalisé | AH2: % | AI2: Objectif | AJ2: Réalisé | AK2: % | AL2: Objectif | AM2: Réalisé | AN2: %
A3: Nombre de visites clients | B3: =+'KPI_VENDEUR 1'!B3+'KPI_VENDEUR 2'!B3+'KPI_VENDEUR 5'!B3+'KPI_VENDEUR 4'!B3+'KPI_VENDEUR 3'!B3 -> 0 | C3: =+'KPI_VENDEUR 1'!C3+'KPI_VENDEUR 2'!C3+'KPI_VENDEUR 5'!C3+'KPI_VENDEUR 4'!C3+'KPI_VENDEUR 3'!C3 -> 0 | D3: =C3/B3 -> #DIV/0! | E3: =+'KPI_VENDEUR 1'!E3+'KPI_VENDEUR 2'!E3+'KPI_VENDEUR 5'!E3+'KPI_VENDEUR 4'!E3+'KPI_VENDEUR 3'!E3 -> 0 | F3: =+'KPI_VENDEUR 1'!F3+'KPI_VENDEUR 2'!F3+'KPI_VENDEUR 5'!F3+'KPI_VENDEUR 4'!F3+'KPI_VENDEUR 3'!F3 -> 0 | G3: =F3/E3 -> #DIV/0! | H3: =+'KPI_VENDEUR 1'!H3+'KPI_VENDEUR 2'!H3+'KPI_VENDEUR 5'!H3+'KPI_VENDEUR 4'!H3+'KPI_VENDEUR 3'!H3 -> 0 | I3: =+'KPI_VENDEUR 1'!I3+'KPI_VENDEUR 2'!I3+'KPI_VENDEUR 5'!I3+'KPI_VENDEUR 4'!I3+'KPI_VENDEUR 3'!I3 -> 0 | J3: =I3/H3 -> #DIV/0! | K3: =+'KPI_VENDEUR 1'!K3+'KPI_VENDEUR 2'!K3+'KPI_VENDEUR 5'!K3+'KPI_VENDEUR 4'!K3+'KPI_VENDEUR 3'!K3 -> 0 | L3: =+'KPI_VENDEUR 1'!L3+'KPI_VENDEUR 2'!L3+'KPI_VENDEUR 5'!L3+'KPI_VENDEUR 4'!L3+'KPI_VENDEUR 3'!L3 -> 0 | M3: =L3/K3 -> #DIV/0! | N3: =+'KPI_VENDEUR 1'!N3+'KPI_VENDEUR 2'!N3+'KPI_VENDEUR 5'!N3+'KPI_VENDEUR 4'!N3+'KPI_VENDEUR 3'!N3 -> 0 | O3: =+'KPI_VENDEUR 1'!O3+'KPI_VENDEUR 2'!O3+'KPI_VENDEUR 5'!O3+'KPI_VENDEUR 4'!O3+'KPI_VENDEUR 3'!O3 -> 0 | P3: =O3/N3 -> #DIV/0! | Q3: =+'KPI_VENDEUR 1'!Q3+'KPI_VENDEUR 2'!Q3+'KPI_VENDEUR 5'!Q3+'KPI_VENDEUR 4'!Q3+'KPI_VENDEUR 3'!Q3 -> 0 | R3: =+'KPI_VENDEUR 1'!R3+'KPI_VENDEUR 2'!R3+'KPI_VENDEUR 5'!R3+'KPI_VENDEUR 4'!R3+'KPI_VENDEUR 3'!R3 -> 0 | S3: =R3/Q3 -> #DIV/0! | T3: =+'KPI_VENDEUR 1'!T3+'KPI_VENDEUR 2'!T3+'KPI_VENDEUR 5'!T3+'KPI_VENDEUR 4'!T3+'KPI_VENDEUR 3'!T3 -> 0 | U3: =+'KPI_VENDEUR 1'!U3+'KPI_VENDEUR 2'!U3+'KPI_VENDEUR 5'!U3+'KPI_VENDEUR 4'!U3+'KPI_VENDEUR 3'!U3 -> 0 | V3: =U3/T3 -> #DIV/0! | W3: =+'KPI_VENDEUR 1'!W3+'KPI_VENDEUR 2'!W3+'KPI_VENDEUR 5'!W3+'KPI_VENDEUR 4'!W3+'KPI_VENDEUR 3'!W3 -> 0 | X3: =+'KPI_VENDEUR 1'!X3+'KPI_VENDEUR 2'!X3+'KPI_VENDEUR 5'!X3+'KPI_VENDEUR 4'!X3+'KPI_VENDEUR 3'!X3 -> 0 | Y3: =X3/W3 -> #DIV/0! | Z3: =+'KPI_VENDEUR 1'!Z3+'KPI_VENDEUR 2'!Z3+'KPI_VENDEUR 5'!Z3+'KPI_VENDEUR 4'!Z3+'KPI_VENDEUR 3'!Z3 -> 0 | AA3: =+'KPI_VENDEUR 1'!AA3+'KPI_VENDEUR 2'!AA3+'KPI_VENDEUR 5'!AA3+'KPI_VENDEUR 4'!AA3+'KPI_VENDEUR 3'!AA3 -> 0 | AB3: =AA3/Z3 -> #DIV/0! | AC3: =+'KPI_VENDEUR 1'!AC3+'KPI_VENDEUR 2'!AC3+'KPI_VENDEUR 5'!AC3+'KPI_VENDEUR 4'!AC3+'KPI_VENDEUR 3'!AC3 -> 0 | AD3: =+'KPI_VENDEUR 1'!AD3+'KPI_VENDEUR 2'!AD3+'KPI_VENDEUR 5'!AD3+'KPI_VENDEUR 4'!AD3+'KPI_VENDEUR 3'!AD3 -> 0 | AE3: =AD3/AC3 -> #DIV/0! | AF3: =+'KPI_VENDEUR 1'!AF3+'KPI_VENDEUR 2'!AF3+'KPI_VENDEUR 5'!AF3+'KPI_VENDEUR 4'!AF3+'KPI_VENDEUR 3'!AF3 -> 0 | AG3: =+'KPI_VENDEUR 1'!AG3+'KPI_VENDEUR 2'!AG3+'KPI_VENDEUR 5'!AG3+'KPI_VENDEUR 4'!AG3+'KPI_VENDEUR 3'!AG3 -> 0 | AH3: =AG3/AF3 -> #DIV/0! | AI3: =+'KPI_VENDEUR 1'!AI3+'KPI_VENDEUR 2'!AI3+'KPI_VENDEUR 5'!AI3+'KPI_VENDEUR 4'!AI3+'KPI_VENDEUR 3'!AI3 -> 0 | AJ3: =+'KPI_VENDEUR 1'!AJ3+'KPI_VENDEUR 2'!AJ3+'KPI_VENDEUR 5'!AJ3+'KPI_VENDEUR 4'!AJ3+'KPI_VENDEUR 3'!AJ3 -> 0 | AK3: =AJ3/AI3 -> #DIV/0! | AL3: =+'KPI_VENDEUR 1'!AL3+'KPI_VENDEUR 2'!AL3+'KPI_VENDEUR 5'!AL3+'KPI_VENDEUR 4'!AL3+'KPI_VENDEUR 3'!AL3 -> 0 | AM3: =+'KPI_VENDEUR 1'!AM3+'KPI_VENDEUR 2'!AM3+'KPI_VENDEUR 5'!AM3+'KPI_VENDEUR 4'!AM3+'KPI_VENDEUR 3'!AM3 -> 0 | AN3: =AM3/AL3 -> #DIV/0!
A4: Nombre d'offres commerciales | B4: =+'KPI_VENDEUR 1'!B4+'KPI_VENDEUR 2'!B4+'KPI_VENDEUR 5'!B4+'KPI_VENDEUR 4'!B4+'KPI_VENDEUR 3'!B4 -> 0 | C4: =+'KPI_VENDEUR 1'!C4+'KPI_VENDEUR 2'!C4+'KPI_VENDEUR 5'!C4+'KPI_VENDEUR 4'!C4+'KPI_VENDEUR 3'!C4 -> 0 | D4: =C4/B4 -> #DIV/0! | E4: =+'KPI_VENDEUR 1'!E4+'KPI_VENDEUR 2'!E4+'KPI_VENDEUR 5'!E4+'KPI_VENDEUR 4'!E4+'KPI_VENDEUR 3'!E4 -> 0 | F4: =+'KPI_VENDEUR 1'!F4+'KPI_VENDEUR 2'!F4+'KPI_VENDEUR 5'!F4+'KPI_VENDEUR 4'!F4+'KPI_VENDEUR 3'!F4 -> 0 | G4: =F4/E4 -> #DIV/0! | H4: =+'KPI_VENDEUR 1'!H4+'KPI_VENDEUR 2'!H4+'KPI_VENDEUR 5'!H4+'KPI_VENDEUR 4'!H4+'KPI_VENDEUR 3'!H4 -> 0 | I4: =+'KPI_VENDEUR 1'!I4+'KPI_VENDEUR 2'!I4+'KPI_VENDEUR 5'!I4+'KPI_VENDEUR 4'!I4+'KPI_VENDEUR 3'!I4 -> 0 | J4: =I4/H4 -> #DIV/0! | K4: =+'KPI_VENDEUR 1'!K4+'KPI_VENDEUR 2'!K4+'KPI_VENDEUR 5'!K4+'KPI_VENDEUR 4'!K4+'KPI_VENDEUR 3'!K4 -> 0 | L4: =+'KPI_VENDEUR 1'!L4+'KPI_VENDEUR 2'!L4+'KPI_VENDEUR 5'!L4+'KPI_VENDEUR 4'!L4+'KPI_VENDEUR 3'!L4 -> 0 | M4: =L4/K4 -> #DIV/0! | N4: =+'KPI_VENDEUR 1'!N4+'KPI_VENDEUR 2'!N4+'KPI_VENDEUR 5'!N4+'KPI_VENDEUR 4'!N4+'KPI_VENDEUR 3'!N4 -> 0 | O4: =+'KPI_VENDEUR 1'!O4+'KPI_VENDEUR 2'!O4+'KPI_VENDEUR 5'!O4+'KPI_VENDEUR 4'!O4+'KPI_VENDEUR 3'!O4 -> 0 | P4: =O4/N4 -> #DIV/0! | Q4: =+'KPI_VENDEUR 1'!Q4+'KPI_VENDEUR 2'!Q4+'KPI_VENDEUR 5'!Q4+'KPI_VENDEUR 4'!Q4+'KPI_VENDEUR 3'!Q4 -> 0 | R4: =+'KPI_VENDEUR 1'!R4+'KPI_VENDEUR 2'!R4+'KPI_VENDEUR 5'!R4+'KPI_VENDEUR 4'!R4+'KPI_VENDEUR 3'!R4 -> 0 | S4: =R4/Q4 -> #DIV/0! | T4: =+'KPI_VENDEUR 1'!T4+'KPI_VENDEUR 2'!T4+'KPI_VENDEUR 5'!T4+'KPI_VENDEUR 4'!T4+'KPI_VENDEUR 3'!T4 -> 0 | U4: =+'KPI_VENDEUR 1'!U4+'KPI_VENDEUR 2'!U4+'KPI_VENDEUR 5'!U4+'KPI_VENDEUR 4'!U4+'KPI_VENDEUR 3'!U4 -> 0 | V4: =U4/T4 -> #DIV/0! | W4: =+'KPI_VENDEUR 1'!W4+'KPI_VENDEUR 2'!W4+'KPI_VENDEUR 5'!W4+'KPI_VENDEUR 4'!W4+'KPI_VENDEUR 3'!W4 -> 0 | X4: =+'KPI_VENDEUR 1'!X4+'KPI_VENDEUR 2'!X4+'KPI_VENDEUR 5'!X4+'KPI_VENDEUR 4'!X4+'KPI_VENDEUR 3'!X4 -> 0 | Y4: =X4/W4 -> #DIV/0! | Z4: =+'KPI_VENDEUR 1'!Z4+'KPI_VENDEUR 2'!Z4+'KPI_VENDEUR 5'!Z4+'KPI_VENDEUR 4'!Z4+'KPI_VENDEUR 3'!Z4 -> 0 | AA4: =+'KPI_VENDEUR 1'!AA4+'KPI_VENDEUR 2'!AA4+'KPI_VENDEUR 5'!AA4+'KPI_VENDEUR 4'!AA4+'KPI_VENDEUR 3'!AA4 -> 0 | AB4: =AA4/Z4 -> #DIV/0! | AC4: =+'KPI_VENDEUR 1'!AC4+'KPI_VENDEUR 2'!AC4+'KPI_VENDEUR 5'!AC4+'KPI_VENDEUR 4'!AC4+'KPI_VENDEUR 3'!AC4 -> 0 | AD4: =+'KPI_VENDEUR 1'!AD4+'KPI_VENDEUR 2'!AD4+'KPI_VENDEUR 5'!AD4+'KPI_VENDEUR 4'!AD4+'KPI_VENDEUR 3'!AD4 -> 0 | AE4: =AD4/AC4 -> #DIV/0! | AF4: =+'KPI_VENDEUR 1'!AF4+'KPI_VENDEUR 2'!AF4+'KPI_VENDEUR 5'!AF4+'KPI_VENDEUR 4'!AF4+'KPI_VENDEUR 3'!AF4 -> 0 | AG4: =+'KPI_VENDEUR 1'!AG4+'KPI_VENDEUR 2'!AG4+'KPI_VENDEUR 5'!AG4+'KPI_VENDEUR 4'!AG4+'KPI_VENDEUR 3'!AG4 -> 0 | AH4: =AG4/AF4 -> #DIV/0! | AI4: =+'KPI_VENDEUR 1'!AI4+'KPI_VENDEUR 2'!AI4+'KPI_VENDEUR 5'!AI4+'KPI_VENDEUR 4'!AI4+'KPI_VENDEUR 3'!AI4 -> 0 | AJ4: =+'KPI_VENDEUR 1'!AJ4+'KPI_VENDEUR 2'!AJ4+'KPI_VENDEUR 5'!AJ4+'KPI_VENDEUR 4'!AJ4+'KPI_VENDEUR 3'!AJ4 -> 0 | AK4: =AJ4/AI4 -> #DIV/0! | AL4: =+'KPI_VENDEUR 1'!AL4+'KPI_VENDEUR 2'!AL4+'KPI_VENDEUR 5'!AL4+'KPI_VENDEUR 4'!AL4+'KPI_VENDEUR 3'!AL4 -> 0 | AM4: =+'KPI_VENDEUR 1'!AM4+'KPI_VENDEUR 2'!AM4+'KPI_VENDEUR 5'!AM4+'KPI_VENDEUR 4'!AM4+'KPI_VENDEUR 3'!AM4 -> 0 | AN4: =AM4/AL4 -> #DIV/0!
A5: Taux de clôture | B5: =+'KPI_VENDEUR 1'!B5+'KPI_VENDEUR 2'!B5+'KPI_VENDEUR 5'!B5+'KPI_VENDEUR 4'!B5+'KPI_VENDEUR 3'!B5 -> 0 | C5: =+'KPI_VENDEUR 1'!C5+'KPI_VENDEUR 2'!C5+'KPI_VENDEUR 5'!C5+'KPI_VENDEUR 4'!C5+'KPI_VENDEUR 3'!C5 -> 0 | D5: =C5/C4 -> #DIV/0! | E5: =+'KPI_VENDEUR 1'!E5+'KPI_VENDEUR 2'!E5+'KPI_VENDEUR 5'!E5+'KPI_VENDEUR 4'!E5+'KPI_VENDEUR 3'!E5 -> 0 | F5: =+'KPI_VENDEUR 1'!F5+'KPI_VENDEUR 2'!F5+'KPI_VENDEUR 5'!F5+'KPI_VENDEUR 4'!F5+'KPI_VENDEUR 3'!F5 -> 0 | G5: =F5/F4 -> #DIV/0! | H5: =+'KPI_VENDEUR 1'!H5+'KPI_VENDEUR 2'!H5+'KPI_VENDEUR 5'!H5+'KPI_VENDEUR 4'!H5+'KPI_VENDEUR 3'!H5 -> 0 | I5: =+'KPI_VENDEUR 1'!I5+'KPI_VENDEUR 2'!I5+'KPI_VENDEUR 5'!I5+'KPI_VENDEUR 4'!I5+'KPI_VENDEUR 3'!I5 -> 0 | J5: =I5/I4 -> #DIV/0! | K5: =+'KPI_VENDEUR 1'!K5+'KPI_VENDEUR 2'!K5+'KPI_VENDEUR 5'!K5+'KPI_VENDEUR 4'!K5+'KPI_VENDEUR 3'!K5 -> 0 | L5: =+'KPI_VENDEUR 1'!L5+'KPI_VENDEUR 2'!L5+'KPI_VENDEUR 5'!L5+'KPI_VENDEUR 4'!L5+'KPI_VENDEUR 3'!L5 -> 0 | M5: =L5/L4 -> #DIV/0! | N5: =+'KPI_VENDEUR 1'!N5+'KPI_VENDEUR 2'!N5+'KPI_VENDEUR 5'!N5+'KPI_VENDEUR 4'!N5+'KPI_VENDEUR 3'!N5 -> 0 | O5: =+'KPI_VENDEUR 1'!O5+'KPI_VENDEUR 2'!O5+'KPI_VENDEUR 5'!O5+'KPI_VENDEUR 4'!O5+'KPI_VENDEUR 3'!O5 -> 0 | P5: =O5/O4 -> #DIV/0! | Q5: =+'KPI_VENDEUR 1'!Q5+'KPI_VENDEUR 2'!Q5+'KPI_VENDEUR 5'!Q5+'KPI_VENDEUR 4'!Q5+'KPI_VENDEUR 3'!Q5 -> 0 | R5: =+'KPI_VENDEUR 1'!R5+'KPI_VENDEUR 2'!R5+'KPI_VENDEUR 5'!R5+'KPI_VENDEUR 4'!R5+'KPI_VENDEUR 3'!R5 -> 0 | S5: =R5/R4 -> #DIV/0! | T5: =+'KPI_VENDEUR 1'!T5+'KPI_VENDEUR 2'!T5+'KPI_VENDEUR 5'!T5+'KPI_VENDEUR 4'!T5+'KPI_VENDEUR 3'!T5 -> 0 | U5: =+'KPI_VENDEUR 1'!U5+'KPI_VENDEUR 2'!U5+'KPI_VENDEUR 5'!U5+'KPI_VENDEUR 4'!U5+'KPI_VENDEUR 3'!U5 -> 0 | V5: =U5/U4 -> #DIV/0! | W5: =+'KPI_VENDEUR 1'!W5+'KPI_VENDEUR 2'!W5+'KPI_VENDEUR 5'!W5+'KPI_VENDEUR 4'!W5+'KPI_VENDEUR 3'!W5 -> 0 | X5: =+'KPI_VENDEUR 1'!X5+'KPI_VENDEUR 2'!X5+'KPI_VENDEUR 5'!X5+'KPI_VENDEUR 4'!X5+'KPI_VENDEUR 3'!X5 -> 0 | Y5: =X5/X4 -> #DIV/0! | Z5: =+'KPI_VENDEUR 1'!Z5+'KPI_VENDEUR 2'!Z5+'KPI_VENDEUR 5'!Z5+'KPI_VENDEUR 4'!Z5+'KPI_VENDEUR 3'!Z5 -> 0 | AA5: =+'KPI_VENDEUR 1'!AA5+'KPI_VENDEUR 2'!AA5+'KPI_VENDEUR 5'!AA5+'KPI_VENDEUR 4'!AA5+'KPI_VENDEUR 3'!AA5 -> 0 | AB5: =AA5/AA4 -> #DIV/0! | AC5: =+'KPI_VENDEUR 1'!AC5+'KPI_VENDEUR 2'!AC5+'KPI_VENDEUR 5'!AC5+'KPI_VENDEUR 4'!AC5+'KPI_VENDEUR 3'!AC5 -> 0 | AD5: =+'KPI_VENDEUR 1'!AD5+'KPI_VENDEUR 2'!AD5+'KPI_VENDEUR 5'!AD5+'KPI_VENDEUR 4'!AD5+'KPI_VENDEUR 3'!AD5 -> 0 | AE5: =AD5/AD4 -> #DIV/0! | AF5: =+'KPI_VENDEUR 1'!AF5+'KPI_VENDEUR 2'!AF5+'KPI_VENDEUR 5'!AF5+'KPI_VENDEUR 4'!AF5+'KPI_VENDEUR 3'!AF5 -> 0 | AG5: =+'KPI_VENDEUR 1'!AG5+'KPI_VENDEUR 2'!AG5+'KPI_VENDEUR 5'!AG5+'KPI_VENDEUR 4'!AG5+'KPI_VENDEUR 3'!AG5 -> 0 | AH5: =AG5/AG4 -> #DIV/0! | AI5: =+'KPI_VENDEUR 1'!AI5+'KPI_VENDEUR 2'!AI5+'KPI_VENDEUR 5'!AI5+'KPI_VENDEUR 4'!AI5+'KPI_VENDEUR 3'!AI5 -> 0 | AJ5: =+'KPI_VENDEUR 1'!AJ5+'KPI_VENDEUR 2'!AJ5+'KPI_VENDEUR 5'!AJ5+'KPI_VENDEUR 4'!AJ5+'KPI_VENDEUR 3'!AJ5 -> 0 | AK5: =AJ5/AJ4 -> #DIV/0! | AL5: =+'KPI_VENDEUR 1'!AL5+'KPI_VENDEUR 2'!AL5+'KPI_VENDEUR 5'!AL5+'KPI_VENDEUR 4'!AL5+'KPI_VENDEUR 3'!AL5 -> 0 | AM5: =+'KPI_VENDEUR 1'!AM5+'KPI_VENDEUR 2'!AM5+'KPI_VENDEUR 5'!AM5+'KPI_VENDEUR 4'!AM5+'KPI_VENDEUR 3'!AM5 -> 0 | AN5: =AM5/AM4 -> #DIV/0!
A6: QTE MANITOU | B6: =+'KPI_VENDEUR 1'!B6+'KPI_VENDEUR 2'!B6+'KPI_VENDEUR 5'!B6+'KPI_VENDEUR 4'!B6+'KPI_VENDEUR 3'!B6 -> 0 | C6: =+'KPI_VENDEUR 1'!C6+'KPI_VENDEUR 2'!C6+'KPI_VENDEUR 5'!C6+'KPI_VENDEUR 4'!C6+'KPI_VENDEUR 3'!C6 -> 0 | D6: =C6/C5 -> #DIV/0! | E6: =+'KPI_VENDEUR 1'!E6+'KPI_VENDEUR 2'!E6+'KPI_VENDEUR 5'!E6+'KPI_VENDEUR 4'!E6+'KPI_VENDEUR 3'!E6 -> 0 | F6: =+'KPI_VENDEUR 1'!F6+'KPI_VENDEUR 2'!F6+'KPI_VENDEUR 5'!F6+'KPI_VENDEUR 4'!F6+'KPI_VENDEUR 3'!F6 -> 0 | G6: =F6/F5 -> #DIV/0! | H6: =+'KPI_VENDEUR 1'!H6+'KPI_VENDEUR 2'!H6+'KPI_VENDEUR 5'!H6+'KPI_VENDEUR 4'!H6+'KPI_VENDEUR 3'!H6 -> 0 | I6: =+'KPI_VENDEUR 1'!I6+'KPI_VENDEUR 2'!I6+'KPI_VENDEUR 5'!I6+'KPI_VENDEUR 4'!I6+'KPI_VENDEUR 3'!I6 -> 0 | J6: =I6/I5 -> #DIV/0! | K6: =+'KPI_VENDEUR 1'!K6+'KPI_VENDEUR 2'!K6+'KPI_VENDEUR 5'!K6+'KPI_VENDEUR 4'!K6+'KPI_VENDEUR 3'!K6 -> 0 | L6: =+'KPI_VENDEUR 1'!L6+'KPI_VENDEUR 2'!L6+'KPI_VENDEUR 5'!L6+'KPI_VENDEUR 4'!L6+'KPI_VENDEUR 3'!L6 -> 0 | M6: =L6/L5 -> #DIV/0! | N6: =+'KPI_VENDEUR 1'!N6+'KPI_VENDEUR 2'!N6+'KPI_VENDEUR 5'!N6+'KPI_VENDEUR 4'!N6+'KPI_VENDEUR 3'!N6 -> 0 | O6: =+'KPI_VENDEUR 1'!O6+'KPI_VENDEUR 2'!O6+'KPI_VENDEUR 5'!O6+'KPI_VENDEUR 4'!O6+'KPI_VENDEUR 3'!O6 -> 0 | P6: =O6/O5 -> #DIV/0! | Q6: =+'KPI_VENDEUR 1'!Q6+'KPI_VENDEUR 2'!Q6+'KPI_VENDEUR 5'!Q6+'KPI_VENDEUR 4'!Q6+'KPI_VENDEUR 3'!Q6 -> 0 | R6: =+'KPI_VENDEUR 1'!R6+'KPI_VENDEUR 2'!R6+'KPI_VENDEUR 5'!R6+'KPI_VENDEUR 4'!R6+'KPI_VENDEUR 3'!R6 -> 0 | S6: =R6/R5 -> #DIV/0! | T6: =+'KPI_VENDEUR 1'!T6+'KPI_VENDEUR 2'!T6+'KPI_VENDEUR 5'!T6+'KPI_VENDEUR 4'!T6+'KPI_VENDEUR 3'!T6 -> 0 | U6: =+'KPI_VENDEUR 1'!U6+'KPI_VENDEUR 2'!U6+'KPI_VENDEUR 5'!U6+'KPI_VENDEUR 4'!U6+'KPI_VENDEUR 3'!U6 -> 0 | V6: =U6/U5 -> #DIV/0! | W6: =+'KPI_VENDEUR 1'!W6+'KPI_VENDEUR 2'!W6+'KPI_VENDEUR 5'!W6+'KPI_VENDEUR 4'!W6+'KPI_VENDEUR 3'!W6 -> 0 | X6: =+'KPI_VENDEUR 1'!X6+'KPI_VENDEUR 2'!X6+'KPI_VENDEUR 5'!X6+'KPI_VENDEUR 4'!X6+'KPI_VENDEUR 3'!X6 -> 0 | Y6: =X6/X5 -> #DIV/0! | Z6: =+'KPI_VENDEUR 1'!Z6+'KPI_VENDEUR 2'!Z6+'KPI_VENDEUR 5'!Z6+'KPI_VENDEUR 4'!Z6+'KPI_VENDEUR 3'!Z6 -> 0 | AA6: =+'KPI_VENDEUR 1'!AA6+'KPI_VENDEUR 2'!AA6+'KPI_VENDEUR 5'!AA6+'KPI_VENDEUR 4'!AA6+'KPI_VENDEUR 3'!AA6 -> 0 | AB6: =AA6/AA5 -> #DIV/0! | AC6: =+'KPI_VENDEUR 1'!AC6+'KPI_VENDEUR 2'!AC6+'KPI_VENDEUR 5'!AC6+'KPI_VENDEUR 4'!AC6+'KPI_VENDEUR 3'!AC6 -> 0 | AD6: =+'KPI_VENDEUR 1'!AD6+'KPI_VENDEUR 2'!AD6+'KPI_VENDEUR 5'!AD6+'KPI_VENDEUR 4'!AD6+'KPI_VENDEUR 3'!AD6 -> 0 | AE6: =AD6/AD5 -> #DIV/0! | AF6: =+'KPI_VENDEUR 1'!AF6+'KPI_VENDEUR 2'!AF6+'KPI_VENDEUR 5'!AF6+'KPI_VENDEUR 4'!AF6+'KPI_VENDEUR 3'!AF6 -> 0 | AG6: =+'KPI_VENDEUR 1'!AG6+'KPI_VENDEUR 2'!AG6+'KPI_VENDEUR 5'!AG6+'KPI_VENDEUR 4'!AG6+'KPI_VENDEUR 3'!AG6 -> 0 | AH6: =AG6/AG5 -> #DIV/0! | AI6: =+'KPI_VENDEUR 1'!AI6+'KPI_VENDEUR 2'!AI6+'KPI_VENDEUR 5'!AI6+'KPI_VENDEUR 4'!AI6+'KPI_VENDEUR 3'!AI6 -> 0 | AJ6: =+'KPI_VENDEUR 1'!AJ6+'KPI_VENDEUR 2'!AJ6+'KPI_VENDEUR 5'!AJ6+'KPI_VENDEUR 4'!AJ6+'KPI_VENDEUR 3'!AJ6 -> 0 | AK6: =AJ6/AJ5 -> #DIV/0! | AL6: =+'KPI_VENDEUR 1'!AL6+'KPI_VENDEUR 2'!AL6+'KPI_VENDEUR 5'!AL6+'KPI_VENDEUR 4'!AL6+'KPI_VENDEUR 3'!AL6 -> 0 | AM6: =+'KPI_VENDEUR 1'!AM6+'KPI_VENDEUR 2'!AM6+'KPI_VENDEUR 5'!AM6+'KPI_VENDEUR 4'!AM6+'KPI_VENDEUR 3'!AM6 -> 0 | AN6: =AM6/AM5 -> #DIV/0!
A7: QTE KALMAR | B7: =+'KPI_VENDEUR 1'!B7+'KPI_VENDEUR 2'!B7+'KPI_VENDEUR 5'!B7+'KPI_VENDEUR 4'!B7+'KPI_VENDEUR 3'!B7 -> 0 | C7: =+'KPI_VENDEUR 1'!C7+'KPI_VENDEUR 2'!C7+'KPI_VENDEUR 5'!C7+'KPI_VENDEUR 4'!C7+'KPI_VENDEUR 3'!C7 -> 0 | D7: =C7/C6 -> #DIV/0! | E7: =+'KPI_VENDEUR 1'!E7+'KPI_VENDEUR 2'!E7+'KPI_VENDEUR 5'!E7+'KPI_VENDEUR 4'!E7+'KPI_VENDEUR 3'!E7 -> 0 | F7: =+'KPI_VENDEUR 1'!F7+'KPI_VENDEUR 2'!F7+'KPI_VENDEUR 5'!F7+'KPI_VENDEUR 4'!F7+'KPI_VENDEUR 3'!F7 -> 0 | G7: =F7/F6 -> #DIV/0! | H7: =+'KPI_VENDEUR 1'!H7+'KPI_VENDEUR 2'!H7+'KPI_VENDEUR 5'!H7+'KPI_VENDEUR 4'!H7+'KPI_VENDEUR 3'!H7 -> 0 | I7: =+'KPI_VENDEUR 1'!I7+'KPI_VENDEUR 2'!I7+'KPI_VENDEUR 5'!I7+'KPI_VENDEUR 4'!I7+'KPI_VENDEUR 3'!I7 -> 0 | J7: =I7/I6 -> #DIV/0! | K7: =+'KPI_VENDEUR 1'!K7+'KPI_VENDEUR 2'!K7+'KPI_VENDEUR 5'!K7+'KPI_VENDEUR 4'!K7+'KPI_VENDEUR 3'!K7 -> 0 | L7: =+'KPI_VENDEUR 1'!L7+'KPI_VENDEUR 2'!L7+'KPI_VENDEUR 5'!L7+'KPI_VENDEUR 4'!L7+'KPI_VENDEUR 3'!L7 -> 0 | M7: =L7/L6 -> #DIV/0! | N7: =+'KPI_VENDEUR 1'!N7+'KPI_VENDEUR 2'!N7+'KPI_VENDEUR 5'!N7+'KPI_VENDEUR 4'!N7+'KPI_VENDEUR 3'!N7 -> 0 | O7: =+'KPI_VENDEUR 1'!O7+'KPI_VENDEUR 2'!O7+'KPI_VENDEUR 5'!O7+'KPI_VENDEUR 4'!O7+'KPI_VENDEUR 3'!O7 -> 0 | P7: =O7/O6 -> #DIV/0! | Q7: =+'KPI_VENDEUR 1'!Q7+'KPI_VENDEUR 2'!Q7+'KPI_VENDEUR 5'!Q7+'KPI_VENDEUR 4'!Q7+'KPI_VENDEUR 3'!Q7 -> 0 | R7: =+'KPI_VENDEUR 1'!R7+'KPI_VENDEUR 2'!R7+'KPI_VENDEUR 5'!R7+'KPI_VENDEUR 4'!R7+'KPI_VENDEUR 3'!R7 -> 0 | S7: =R7/R6 -> #DIV/0! | T7: =+'KPI_VENDEUR 1'!T7+'KPI_VENDEUR 2'!T7+'KPI_VENDEUR 5'!T7+'KPI_VENDEUR 4'!T7+'KPI_VENDEUR 3'!T7 -> 0 | U7: =+'KPI_VENDEUR 1'!U7+'KPI_VENDEUR 2'!U7+'KPI_VENDEUR 5'!U7+'KPI_VENDEUR 4'!U7+'KPI_VENDEUR 3'!U7 -> 0 | V7: =U7/U6 -> #DIV/0! | W7: =+'KPI_VENDEUR 1'!W7+'KPI_VENDEUR 2'!W7+'KPI_VENDEUR 5'!W7+'KPI_VENDEUR 4'!W7+'KPI_VENDEUR 3'!W7 -> 0 | X7: =+'KPI_VENDEUR 1'!X7+'KPI_VENDEUR 2'!X7+'KPI_VENDEUR 5'!X7+'KPI_VENDEUR 4'!X7+'KPI_VENDEUR 3'!X7 -> 0 | Y7: =X7/X6 -> #DIV/0! | Z7: =+'KPI_VENDEUR 1'!Z7+'KPI_VENDEUR 2'!Z7+'KPI_VENDEUR 5'!Z7+'KPI_VENDEUR 4'!Z7+'KPI_VENDEUR 3'!Z7 -> 0 | AA7: =+'KPI_VENDEUR 1'!AA7+'KPI_VENDEUR 2'!AA7+'KPI_VENDEUR 5'!AA7+'KPI_VENDEUR 4'!AA7+'KPI_VENDEUR 3'!AA7 -> 0 | AB7: =AA7/AA6 -> #DIV/0! | AC7: =+'KPI_VENDEUR 1'!AC7+'KPI_VENDEUR 2'!AC7+'KPI_VENDEUR 5'!AC7+'KPI_VENDEUR 4'!AC7+'KPI_VENDEUR 3'!AC7 -> 0 | AD7: =+'KPI_VENDEUR 1'!AD7+'KPI_VENDEUR 2'!AD7+'KPI_VENDEUR 5'!AD7+'KPI_VENDEUR 4'!AD7+'KPI_VENDEUR 3'!AD7 -> 0 | AE7: =AD7/AD6 -> #DIV/0! | AF7: =+'KPI_VENDEUR 1'!AF7+'KPI_VENDEUR 2'!AF7+'KPI_VENDEUR 5'!AF7+'KPI_VENDEUR 4'!AF7+'KPI_VENDEUR 3'!AF7 -> 0 | AG7: =+'KPI_VENDEUR 1'!AG7+'KPI_VENDEUR 2'!AG7+'KPI_VENDEUR 5'!AG7+'KPI_VENDEUR 4'!AG7+'KPI_VENDEUR 3'!AG7 -> 0 | AH7: =AG7/AG6 -> #DIV/0! | AI7: =+'KPI_VENDEUR 1'!AI7+'KPI_VENDEUR 2'!AI7+'KPI_VENDEUR 5'!AI7+'KPI_VENDEUR 4'!AI7+'KPI_VENDEUR 3'!AI7 -> 0 | AJ7: =+'KPI_VENDEUR 1'!AJ7+'KPI_VENDEUR 2'!AJ7+'KPI_VENDEUR 5'!AJ7+'KPI_VENDEUR 4'!AJ7+'KPI_VENDEUR 3'!AJ7 -> 0 | AK7: =AJ7/AJ6 -> #DIV/0! | AL7: =+'KPI_VENDEUR 1'!AL7+'KPI_VENDEUR 2'!AL7+'KPI_VENDEUR 5'!AL7+'KPI_VENDEUR 4'!AL7+'KPI_VENDEUR 3'!AL7 -> 0 | AM7: =+'KPI_VENDEUR 1'!AM7+'KPI_VENDEUR 2'!AM7+'KPI_VENDEUR 5'!AM7+'KPI_VENDEUR 4'!AM7+'KPI_VENDEUR 3'!AM7 -> 0 | AN7: =AM7/AM6 -> #DIV/0!
A8: QTE MASSEY FERGUSON | B8: =+'KPI_VENDEUR 1'!B8+'KPI_VENDEUR 2'!B8+'KPI_VENDEUR 5'!B8+'KPI_VENDEUR 4'!B8+'KPI_VENDEUR 3'!B8 -> 0 | C8: =+'KPI_VENDEUR 1'!C8+'KPI_VENDEUR 2'!C8+'KPI_VENDEUR 5'!C8+'KPI_VENDEUR 4'!C8+'KPI_VENDEUR 3'!C8 -> 0 | D8: =C8/C7 -> #DIV/0! | E8: =+'KPI_VENDEUR 1'!E8+'KPI_VENDEUR 2'!E8+'KPI_VENDEUR 5'!E8+'KPI_VENDEUR 4'!E8+'KPI_VENDEUR 3'!E8 -> 0 | F8: =+'KPI_VENDEUR 1'!F8+'KPI_VENDEUR 2'!F8+'KPI_VENDEUR 5'!F8+'KPI_VENDEUR 4'!F8+'KPI_VENDEUR 3'!F8 -> 0 | G8: =F8/F7 -> #DIV/0! | H8: =+'KPI_VENDEUR 1'!H8+'KPI_VENDEUR 2'!H8+'KPI_VENDEUR 5'!H8+'KPI_VENDEUR 4'!H8+'KPI_VENDEUR 3'!H8 -> 0 | I8: =+'KPI_VENDEUR 1'!I8+'KPI_VENDEUR 2'!I8+'KPI_VENDEUR 5'!I8+'KPI_VENDEUR 4'!I8+'KPI_VENDEUR 3'!I8 -> 0 | J8: =I8/I7 -> #DIV/0! | K8: =+'KPI_VENDEUR 1'!K8+'KPI_VENDEUR 2'!K8+'KPI_VENDEUR 5'!K8+'KPI_VENDEUR 4'!K8+'KPI_VENDEUR 3'!K8 -> 0 | L8: =+'KPI_VENDEUR 1'!L8+'KPI_VENDEUR 2'!L8+'KPI_VENDEUR 5'!L8+'KPI_VENDEUR 4'!L8+'KPI_VENDEUR 3'!L8 -> 0 | M8: =L8/L7 -> #DIV/0! | N8: =+'KPI_VENDEUR 1'!N8+'KPI_VENDEUR 2'!N8+'KPI_VENDEUR 5'!N8+'KPI_VENDEUR 4'!N8+'KPI_VENDEUR 3'!N8 -> 0 | O8: =+'KPI_VENDEUR 1'!O8+'KPI_VENDEUR 2'!O8+'KPI_VENDEUR 5'!O8+'KPI_VENDEUR 4'!O8+'KPI_VENDEUR 3'!O8 -> 0 | P8: =O8/O7 -> #DIV/0! | Q8: =+'KPI_VENDEUR 1'!Q8+'KPI_VENDEUR 2'!Q8+'KPI_VENDEUR 5'!Q8+'KPI_VENDEUR 4'!Q8+'KPI_VENDEUR 3'!Q8 -> 0 | R8: =+'KPI_VENDEUR 1'!R8+'KPI_VENDEUR 2'!R8+'KPI_VENDEUR 5'!R8+'KPI_VENDEUR 4'!R8+'KPI_VENDEUR 3'!R8 -> 0 | S8: =R8/R7 -> #DIV/0! | T8: =+'KPI_VENDEUR 1'!T8+'KPI_VENDEUR 2'!T8+'KPI_VENDEUR 5'!T8+'KPI_VENDEUR 4'!T8+'KPI_VENDEUR 3'!T8 -> 0 | U8: =+'KPI_VENDEUR 1'!U8+'KPI_VENDEUR 2'!U8+'KPI_VENDEUR 5'!U8+'KPI_VENDEUR 4'!U8+'KPI_VENDEUR 3'!U8 -> 0 | V8: =U8/U7 -> #DIV/0! | W8: =+'KPI_VENDEUR 1'!W8+'KPI_VENDEUR 2'!W8+'KPI_VENDEUR 5'!W8+'KPI_VENDEUR 4'!W8+'KPI_VENDEUR 3'!W8 -> 0 | X8: =+'KPI_VENDEUR 1'!X8+'KPI_VENDEUR 2'!X8+'KPI_VENDEUR 5'!X8+'KPI_VENDEUR 4'!X8+'KPI_VENDEUR 3'!X8 -> 0 | Y8: =X8/X7 -> #DIV/0! | Z8: =+'KPI_VENDEUR 1'!Z8+'KPI_VENDEUR 2'!Z8+'KPI_VENDEUR 5'!Z8+'KPI_VENDEUR 4'!Z8+'KPI_VENDEUR 3'!Z8 -> 0 | AA8: =+'KPI_VENDEUR 1'!AA8+'KPI_VENDEUR 2'!AA8+'KPI_VENDEUR 5'!AA8+'KPI_VENDEUR 4'!AA8+'KPI_VENDEUR 3'!AA8 -> 0 | AB8: =AA8/AA7 -> #DIV/0! | AC8: =+'KPI_VENDEUR 1'!AC8+'KPI_VENDEUR 2'!AC8+'KPI_VENDEUR 5'!AC8+'KPI_VENDEUR 4'!AC8+'KPI_VENDEUR 3'!AC8 -> 0 | AD8: =+'KPI_VENDEUR 1'!AD8+'KPI_VENDEUR 2'!AD8+'KPI_VENDEUR 5'!AD8+'KPI_VENDEUR 4'!AD8+'KPI_VENDEUR 3'!AD8 -> 0 | AE8: =AD8/AD7 -> #DIV/0! | AF8: =+'KPI_VENDEUR 1'!AF8+'KPI_VENDEUR 2'!AF8+'KPI_VENDEUR 5'!AF8+'KPI_VENDEUR 4'!AF8+'KPI_VENDEUR 3'!AF8 -> 0 | AG8: =+'KPI_VENDEUR 1'!AG8+'KPI_VENDEUR 2'!AG8+'KPI_VENDEUR 5'!AG8+'KPI_VENDEUR 4'!AG8+'KPI_VENDEUR 3'!AG8 -> 0 | AH8: =AG8/AG7 -> #DIV/0! | AI8: =+'KPI_VENDEUR 1'!AI8+'KPI_VENDEUR 2'!AI8+'KPI_VENDEUR 5'!AI8+'KPI_VENDEUR 4'!AI8+'KPI_VENDEUR 3'!AI8 -> 0 | AJ8: =+'KPI_VENDEUR 1'!AJ8+'KPI_VENDEUR 2'!AJ8+'KPI_VENDEUR 5'!AJ8+'KPI_VENDEUR 4'!AJ8+'KPI_VENDEUR 3'!AJ8 -> 0 | AK8: =AJ8/AJ7 -> #DIV/0! | AL8: =+'KPI_VENDEUR 1'!AL8+'KPI_VENDEUR 2'!AL8+'KPI_VENDEUR 5'!AL8+'KPI_VENDEUR 4'!AL8+'KPI_VENDEUR 3'!AL8 -> 0 | AM8: =+'KPI_VENDEUR 1'!AM8+'KPI_VENDEUR 2'!AM8+'KPI_VENDEUR 5'!AM8+'KPI_VENDEUR 4'!AM8+'KPI_VENDEUR 3'!AM8 -> 0 | AN8: =AM8/AM7 -> #DIV/0!
A9: QTE NARDI | B9: =+'KPI_VENDEUR 1'!B9+'KPI_VENDEUR 2'!B9+'KPI_VENDEUR 5'!B9+'KPI_VENDEUR 4'!B9+'KPI_VENDEUR 3'!B9 -> 0 | C9: =+'KPI_VENDEUR 1'!C9+'KPI_VENDEUR 2'!C9+'KPI_VENDEUR 5'!C9+'KPI_VENDEUR 4'!C9+'KPI_VENDEUR 3'!C9 -> 0 | D9: =C9/C8 -> #DIV/0! | E9: =+'KPI_VENDEUR 1'!E9+'KPI_VENDEUR 2'!E9+'KPI_VENDEUR 5'!E9+'KPI_VENDEUR 4'!E9+'KPI_VENDEUR 3'!E9 -> 0 | F9: =+'KPI_VENDEUR 1'!F9+'KPI_VENDEUR 2'!F9+'KPI_VENDEUR 5'!F9+'KPI_VENDEUR 4'!F9+'KPI_VENDEUR 3'!F9 -> 0 | G9: =F9/F8 -> #DIV/0! | H9: =+'KPI_VENDEUR 1'!H9+'KPI_VENDEUR 2'!H9+'KPI_VENDEUR 5'!H9+'KPI_VENDEUR 4'!H9+'KPI_VENDEUR 3'!H9 -> 0 | I9: =+'KPI_VENDEUR 1'!I9+'KPI_VENDEUR 2'!I9+'KPI_VENDEUR 5'!I9+'KPI_VENDEUR 4'!I9+'KPI_VENDEUR 3'!I9 -> 0 | J9: =I9/I8 -> #DIV/0! | K9: =+'KPI_VENDEUR 1'!K9+'KPI_VENDEUR 2'!K9+'KPI_VENDEUR 5'!K9+'KPI_VENDEUR 4'!K9+'KPI_VENDEUR 3'!K9 -> 0 | L9: =+'KPI_VENDEUR 1'!L9+'KPI_VENDEUR 2'!L9+'KPI_VENDEUR 5'!L9+'KPI_VENDEUR 4'!L9+'KPI_VENDEUR 3'!L9 -> 0 | M9: =L9/L8 -> #DIV/0! | N9: =+'KPI_VENDEUR 1'!N9+'KPI_VENDEUR 2'!N9+'KPI_VENDEUR 5'!N9+'KPI_VENDEUR 4'!N9+'KPI_VENDEUR 3'!N9 -> 0 | O9: =+'KPI_VENDEUR 1'!O9+'KPI_VENDEUR 2'!O9+'KPI_VENDEUR 5'!O9+'KPI_VENDEUR 4'!O9+'KPI_VENDEUR 3'!O9 -> 0 | P9: =O9/O8 -> #DIV/0! | Q9: =+'KPI_VENDEUR 1'!Q9+'KPI_VENDEUR 2'!Q9+'KPI_VENDEUR 5'!Q9+'KPI_VENDEUR 4'!Q9+'KPI_VENDEUR 3'!Q9 -> 0 | R9: =+'KPI_VENDEUR 1'!R9+'KPI_VENDEUR 2'!R9+'KPI_VENDEUR 5'!R9+'KPI_VENDEUR 4'!R9+'KPI_VENDEUR 3'!R9 -> 0 | S9: =R9/R8 -> #DIV/0! | T9: =+'KPI_VENDEUR 1'!T9+'KPI_VENDEUR 2'!T9+'KPI_VENDEUR 5'!T9+'KPI_VENDEUR 4'!T9+'KPI_VENDEUR 3'!T9 -> 0 | U9: =+'KPI_VENDEUR 1'!U9+'KPI_VENDEUR 2'!U9+'KPI_VENDEUR 5'!U9+'KPI_VENDEUR 4'!U9+'KPI_VENDEUR 3'!U9 -> 0 | V9: =U9/U8 -> #DIV/0! | W9: =+'KPI_VENDEUR 1'!W9+'KPI_VENDEUR 2'!W9+'KPI_VENDEUR 5'!W9+'KPI_VENDEUR 4'!W9+'KPI_VENDEUR 3'!W9 -> 0 | X9: =+'KPI_VENDEUR 1'!X9+'KPI_VENDEUR 2'!X9+'KPI_VENDEUR 5'!X9+'KPI_VENDEUR 4'!X9+'KPI_VENDEUR 3'!X9 -> 0 | Y9: =X9/X8 -> #DIV/0! | Z9: =+'KPI_VENDEUR 1'!Z9+'KPI_VENDEUR 2'!Z9+'KPI_VENDEUR 5'!Z9+'KPI_VENDEUR 4'!Z9+'KPI_VENDEUR 3'!Z9 -> 0 | AA9: =+'KPI_VENDEUR 1'!AA9+'KPI_VENDEUR 2'!AA9+'KPI_VENDEUR 5'!AA9+'KPI_VENDEUR 4'!AA9+'KPI_VENDEUR 3'!AA9 -> 0 | AB9: =AA9/AA8 -> #DIV/0! | AC9: =+'KPI_VENDEUR 1'!AC9+'KPI_VENDEUR 2'!AC9+'KPI_VENDEUR 5'!AC9+'KPI_VENDEUR 4'!AC9+'KPI_VENDEUR 3'!AC9 -> 0 | AD9: =+'KPI_VENDEUR 1'!AD9+'KPI_VENDEUR 2'!AD9+'KPI_VENDEUR 5'!AD9+'KPI_VENDEUR 4'!AD9+'KPI_VENDEUR 3'!AD9 -> 0 | AE9: =AD9/AD8 -> #DIV/0! | AF9: =+'KPI_VENDEUR 1'!AF9+'KPI_VENDEUR 2'!AF9+'KPI_VENDEUR 5'!AF9+'KPI_VENDEUR 4'!AF9+'KPI_VENDEUR 3'!AF9 -> 0 | AG9: =+'KPI_VENDEUR 1'!AG9+'KPI_VENDEUR 2'!AG9+'KPI_VENDEUR 5'!AG9+'KPI_VENDEUR 4'!AG9+'KPI_VENDEUR 3'!AG9 -> 0 | AH9: =AG9/AG8 -> #DIV/0! | AI9: =+'KPI_VENDEUR 1'!AI9+'KPI_VENDEUR 2'!AI9+'KPI_VENDEUR 5'!AI9+'KPI_VENDEUR 4'!AI9+'KPI_VENDEUR 3'!AI9 -> 0 | AJ9: =+'KPI_VENDEUR 1'!AJ9+'KPI_VENDEUR 2'!AJ9+'KPI_VENDEUR 5'!AJ9+'KPI_VENDEUR 4'!AJ9+'KPI_VENDEUR 3'!AJ9 -> 0 | AK9: =AJ9/AJ8 -> #DIV/0! | AL9: =+'KPI_VENDEUR 1'!AL9+'KPI_VENDEUR 2'!AL9+'KPI_VENDEUR 5'!AL9+'KPI_VENDEUR 4'!AL9+'KPI_VENDEUR 3'!AL9 -> 0 | AM9: =+'KPI_VENDEUR 1'!AM9+'KPI_VENDEUR 2'!AM9+'KPI_VENDEUR 5'!AM9+'KPI_VENDEUR 4'!AM9+'KPI_VENDEUR 3'!AM9 -> 0 | AN9: =AM9/AM8 -> #DIV/0!
A10: QTE TOTAL VENTES | B10: =+'KPI_VENDEUR 1'!B10+'KPI_VENDEUR 2'!B10+'KPI_VENDEUR 5'!B10+'KPI_VENDEUR 4'!B10+'KPI_VENDEUR 3'!B10 -> 0 | C10: =+'KPI_VENDEUR 1'!C10+'KPI_VENDEUR 2'!C10+'KPI_VENDEUR 5'!C10+'KPI_VENDEUR 4'!C10+'KPI_VENDEUR 3'!C10 -> 0 | D10: =C10/B10 -> #DIV/0! | E10: =+'KPI_VENDEUR 1'!E10+'KPI_VENDEUR 2'!E10+'KPI_VENDEUR 5'!E10+'KPI_VENDEUR 4'!E10+'KPI_VENDEUR 3'!E10 -> 0 | F10: =+'KPI_VENDEUR 1'!F10+'KPI_VENDEUR 2'!F10+'KPI_VENDEUR 5'!F10+'KPI_VENDEUR 4'!F10+'KPI_VENDEUR 3'!F10 -> 0 | G10: =F10/E10 -> #DIV/0! | H10: =+'KPI_VENDEUR 1'!H10+'KPI_VENDEUR 2'!H10+'KPI_VENDEUR 5'!H10+'KPI_VENDEUR 4'!H10+'KPI_VENDEUR 3'!H10 -> 0 | I10: =+'KPI_VENDEUR 1'!I10+'KPI_VENDEUR 2'!I10+'KPI_VENDEUR 5'!I10+'KPI_VENDEUR 4'!I10+'KPI_VENDEUR 3'!I10 -> 0 | J10: =I10/H10 -> #DIV/0! | K10: =+'KPI_VENDEUR 1'!K10+'KPI_VENDEUR 2'!K10+'KPI_VENDEUR 5'!K10+'KPI_VENDEUR 4'!K10+'KPI_VENDEUR 3'!K10 -> 0 | L10: =+'KPI_VENDEUR 1'!L10+'KPI_VENDEUR 2'!L10+'KPI_VENDEUR 5'!L10+'KPI_VENDEUR 4'!L10+'KPI_VENDEUR 3'!L10 -> 0 | M10: =L10/K10 -> #DIV/0! | N10: =+'KPI_VENDEUR 1'!N10+'KPI_VENDEUR 2'!N10+'KPI_VENDEUR 5'!N10+'KPI_VENDEUR 4'!N10+'KPI_VENDEUR 3'!N10 -> 0 | O10: =+'KPI_VENDEUR 1'!O10+'KPI_VENDEUR 2'!O10+'KPI_VENDEUR 5'!O10+'KPI_VENDEUR 4'!O10+'KPI_VENDEUR 3'!O10 -> 0 | P10: =O10/N10 -> #DIV/0! | Q10: =+'KPI_VENDEUR 1'!Q10+'KPI_VENDEUR 2'!Q10+'KPI_VENDEUR 5'!Q10+'KPI_VENDEUR 4'!Q10+'KPI_VENDEUR 3'!Q10 -> 0 | R10: =+'KPI_VENDEUR 1'!R10+'KPI_VENDEUR 2'!R10+'KPI_VENDEUR 5'!R10+'KPI_VENDEUR 4'!R10+'KPI_VENDEUR 3'!R10 -> 0 | S10: =R10/Q10 -> #DIV/0! | T10: =+'KPI_VENDEUR 1'!T10+'KPI_VENDEUR 2'!T10+'KPI_VENDEUR 5'!T10+'KPI_VENDEUR 4'!T10+'KPI_VENDEUR 3'!T10 -> 0 | U10: =+'KPI_VENDEUR 1'!U10+'KPI_VENDEUR 2'!U10+'KPI_VENDEUR 5'!U10+'KPI_VENDEUR 4'!U10+'KPI_VENDEUR 3'!U10 -> 0 | V10: =U10/T10 -> #DIV/0! | W10: =+'KPI_VENDEUR 1'!W10+'KPI_VENDEUR 2'!W10+'KPI_VENDEUR 5'!W10+'KPI_VENDEUR 4'!W10+'KPI_VENDEUR 3'!W10 -> 0 | X10: =+'KPI_VENDEUR 1'!X10+'KPI_VENDEUR 2'!X10+'KPI_VENDEUR 5'!X10+'KPI_VENDEUR 4'!X10+'KPI_VENDEUR 3'!X10 -> 0 | Y10: =X10/W10 -> #DIV/0! | Z10: =+'KPI_VENDEUR 1'!Z10+'KPI_VENDEUR 2'!Z10+'KPI_VENDEUR 5'!Z10+'KPI_VENDEUR 4'!Z10+'KPI_VENDEUR 3'!Z10 -> 0 | AA10: =+'KPI_VENDEUR 1'!AA10+'KPI_VENDEUR 2'!AA10+'KPI_VENDEUR 5'!AA10+'KPI_VENDEUR 4'!AA10+'KPI_VENDEUR 3'!AA10 -> 0 | AB10: =AA10/Z10 -> #DIV/0! | AC10: =+'KPI_VENDEUR 1'!AC10+'KPI_VENDEUR 2'!AC10+'KPI_VENDEUR 5'!AC10+'KPI_VENDEUR 4'!AC10+'KPI_VENDEUR 3'!AC10 -> 0 | AD10: =+'KPI_VENDEUR 1'!AD10+'KPI_VENDEUR 2'!AD10+'KPI_VENDEUR 5'!AD10+'KPI_VENDEUR 4'!AD10+'KPI_VENDEUR 3'!AD10 -> 0 | AE10: =AD10/AC10 -> #DIV/0! | AF10: =+'KPI_VENDEUR 1'!AF10+'KPI_VENDEUR 2'!AF10+'KPI_VENDEUR 5'!AF10+'KPI_VENDEUR 4'!AF10+'KPI_VENDEUR 3'!AF10 -> 0 | AG10: =+'KPI_VENDEUR 1'!AG10+'KPI_VENDEUR 2'!AG10+'KPI_VENDEUR 5'!AG10+'KPI_VENDEUR 4'!AG10+'KPI_VENDEUR 3'!AG10 -> 0 | AH10: =AG10/AF10 -> #DIV/0! | AI10: =+'KPI_VENDEUR 1'!AI10+'KPI_VENDEUR 2'!AI10+'KPI_VENDEUR 5'!AI10+'KPI_VENDEUR 4'!AI10+'KPI_VENDEUR 3'!AI10 -> 0 | AJ10: =+'KPI_VENDEUR 1'!AJ10+'KPI_VENDEUR 2'!AJ10+'KPI_VENDEUR 5'!AJ10+'KPI_VENDEUR 4'!AJ10+'KPI_VENDEUR 3'!AJ10 -> 0 | AK10: =AJ10/AI10 -> #DIV/0! | AL10: =+'KPI_VENDEUR 1'!AL10+'KPI_VENDEUR 2'!AL10+'KPI_VENDEUR 5'!AL10+'KPI_VENDEUR 4'!AL10+'KPI_VENDEUR 3'!AL10 -> 0 | AM10: =+'KPI_VENDEUR 1'!AM10+'KPI_VENDEUR 2'!AM10+'KPI_VENDEUR 5'!AM10+'KPI_VENDEUR 4'!AM10+'KPI_VENDEUR 3'!AM10 -> 0 | AN10: =AM10/AL10 -> #DIV/0!
A11: Chiffre d'Affaires (HT) FCFA | B11: =+'KPI_VENDEUR 1'!B11+'KPI_VENDEUR 2'!B11+'KPI_VENDEUR 5'!B11+'KPI_VENDEUR 4'!B11+'KPI_VENDEUR 3'!B11 -> 0 | C11: =+'KPI_VENDEUR 1'!C11+'KPI_VENDEUR 2'!C11+'KPI_VENDEUR 5'!C11+'KPI_VENDEUR 4'!C11+'KPI_VENDEUR 3'!C11 -> 0 | D11: =C11/B11 -> #DIV/0! | E11: =+'KPI_VENDEUR 1'!E11+'KPI_VENDEUR 2'!E11+'KPI_VENDEUR 5'!E11+'KPI_VENDEUR 4'!E11+'KPI_VENDEUR 3'!E11 -> 0 | F11: =+'KPI_VENDEUR 1'!F11+'KPI_VENDEUR 2'!F11+'KPI_VENDEUR 5'!F11+'KPI_VENDEUR 4'!F11+'KPI_VENDEUR 3'!F11 -> 0 | G11: =F11/E11 -> #DIV/0! | H11: =+'KPI_VENDEUR 1'!H11+'KPI_VENDEUR 2'!H11+'KPI_VENDEUR 5'!H11+'KPI_VENDEUR 4'!H11+'KPI_VENDEUR 3'!H11 -> 0 | I11: =+'KPI_VENDEUR 1'!I11+'KPI_VENDEUR 2'!I11+'KPI_VENDEUR 5'!I11+'KPI_VENDEUR 4'!I11+'KPI_VENDEUR 3'!I11 -> 0 | J11: =I11/H11 -> #DIV/0! | K11: =+'KPI_VENDEUR 1'!K11+'KPI_VENDEUR 2'!K11+'KPI_VENDEUR 5'!K11+'KPI_VENDEUR 4'!K11+'KPI_VENDEUR 3'!K11 -> 0 | L11: =+'KPI_VENDEUR 1'!L11+'KPI_VENDEUR 2'!L11+'KPI_VENDEUR 5'!L11+'KPI_VENDEUR 4'!L11+'KPI_VENDEUR 3'!L11 -> 0 | M11: =L11/K11 -> #DIV/0! | N11: =+'KPI_VENDEUR 1'!N11+'KPI_VENDEUR 2'!N11+'KPI_VENDEUR 5'!N11+'KPI_VENDEUR 4'!N11+'KPI_VENDEUR 3'!N11 -> 0 | O11: =+'KPI_VENDEUR 1'!O11+'KPI_VENDEUR 2'!O11+'KPI_VENDEUR 5'!O11+'KPI_VENDEUR 4'!O11+'KPI_VENDEUR 3'!O11 -> 0 | P11: =O11/N11 -> #DIV/0! | Q11: =+'KPI_VENDEUR 1'!Q11+'KPI_VENDEUR 2'!Q11+'KPI_VENDEUR 5'!Q11+'KPI_VENDEUR 4'!Q11+'KPI_VENDEUR 3'!Q11 -> 0 | R11: =+'KPI_VENDEUR 1'!R11+'KPI_VENDEUR 2'!R11+'KPI_VENDEUR 5'!R11+'KPI_VENDEUR 4'!R11+'KPI_VENDEUR 3'!R11 -> 0 | S11: =R11/Q11 -> #DIV/0! | T11: =+'KPI_VENDEUR 1'!T11+'KPI_VENDEUR 2'!T11+'KPI_VENDEUR 5'!T11+'KPI_VENDEUR 4'!T11+'KPI_VENDEUR 3'!T11 -> 0 | U11: =+'KPI_VENDEUR 1'!U11+'KPI_VENDEUR 2'!U11+'KPI_VENDEUR 5'!U11+'KPI_VENDEUR 4'!U11+'KPI_VENDEUR 3'!U11 -> 0 | V11: =U11/T11 -> #DIV/0! | W11: =+'KPI_VENDEUR 1'!W11+'KPI_VENDEUR 2'!W11+'KPI_VENDEUR 5'!W11+'KPI_VENDEUR 4'!W11+'KPI_VENDEUR 3'!W11 -> 0 | X11: =+'KPI_VENDEUR 1'!X11+'KPI_VENDEUR 2'!X11+'KPI_VENDEUR 5'!X11+'KPI_VENDEUR 4'!X11+'KPI_VENDEUR 3'!X11 -> 0 | Y11: =X11/W11 -> #DIV/0! | Z11: =+'KPI_VENDEUR 1'!Z11+'KPI_VENDEUR 2'!Z11+'KPI_VENDEUR 5'!Z11+'KPI_VENDEUR 4'!Z11+'KPI_VENDEUR 3'!Z11 -> 0 | AA11: =+'KPI_VENDEUR 1'!AA11+'KPI_VENDEUR 2'!AA11+'KPI_VENDEUR 5'!AA11+'KPI_VENDEUR 4'!AA11+'KPI_VENDEUR 3'!AA11 -> 0 | AB11: =AA11/Z11 -> #DIV/0! | AC11: =+'KPI_VENDEUR 1'!AC11+'KPI_VENDEUR 2'!AC11+'KPI_VENDEUR 5'!AC11+'KPI_VENDEUR 4'!AC11+'KPI_VENDEUR 3'!AC11 -> 0 | AD11: =+'KPI_VENDEUR 1'!AD11+'KPI_VENDEUR 2'!AD11+'KPI_VENDEUR 5'!AD11+'KPI_VENDEUR 4'!AD11+'KPI_VENDEUR 3'!AD11 -> 0 | AE11: =AD11/AC11 -> #DIV/0! | AF11: =+'KPI_VENDEUR 1'!AF11+'KPI_VENDEUR 2'!AF11+'KPI_VENDEUR 5'!AF11+'KPI_VENDEUR 4'!AF11+'KPI_VENDEUR 3'!AF11 -> 0 | AG11: =+'KPI_VENDEUR 1'!AG11+'KPI_VENDEUR 2'!AG11+'KPI_VENDEUR 5'!AG11+'KPI_VENDEUR 4'!AG11+'KPI_VENDEUR 3'!AG11 -> 0 | AH11: =AG11/AF11 -> #DIV/0! | AI11: =+'KPI_VENDEUR 1'!AI11+'KPI_VENDEUR 2'!AI11+'KPI_VENDEUR 5'!AI11+'KPI_VENDEUR 4'!AI11+'KPI_VENDEUR 3'!AI11 -> 0 | AJ11: =+'KPI_VENDEUR 1'!AJ11+'KPI_VENDEUR 2'!AJ11+'KPI_VENDEUR 5'!AJ11+'KPI_VENDEUR 4'!AJ11+'KPI_VENDEUR 3'!AJ11 -> 0 | AK11: =AJ11/AI11 -> #DIV/0! | AL11: =+'KPI_VENDEUR 1'!AL11+'KPI_VENDEUR 2'!AL11+'KPI_VENDEUR 5'!AL11+'KPI_VENDEUR 4'!AL11+'KPI_VENDEUR 3'!AL11 -> 0 | AM11: =+'KPI_VENDEUR 1'!AM11+'KPI_VENDEUR 2'!AM11+'KPI_VENDEUR 5'!AM11+'KPI_VENDEUR 4'!AM11+'KPI_VENDEUR 3'!AM11 -> 0 | AN11: =AM11/AL11 -> #DIV/0!
A12: Nombre de Machines en stock | C12: =+'KPI_VENDEUR 1'!C12 -> #DIV/0! | F12: =+'KPI_VENDEUR 1'!F12 -> 0 | I12: =+'KPI_VENDEUR 1'!I12 -> 0 | L12: =+'KPI_VENDEUR 1'!L12 -> 0 | O12: =+'KPI_VENDEUR 1'!O12 -> 0 | R12: =+'KPI_VENDEUR 1'!R12 -> 0 | U12: =+'KPI_VENDEUR 1'!U12 -> 0 | X12: =+'KPI_VENDEUR 1'!X12 -> 0 | AA12: =+'KPI_VENDEUR 1'!AA12 -> 0 | AD12: =+'KPI_VENDEUR 1'!AD12 -> 0 | AG12: =+'KPI_VENDEUR 1'!AG12 -> 0 | AJ12: =+'KPI_VENDEUR 1'!AJ12 -> 0 | AM12: =+'KPI_VENDEUR 1'!AM12 -> 0
A13: Valeur stock Machines FCFA | C13: =+'KPI_VENDEUR 1'!C13 -> #DIV/0! | F13: =+'KPI_VENDEUR 1'!F13 -> 0 | I13: =+'KPI_VENDEUR 1'!I13 -> 0 | L13: =+'KPI_VENDEUR 1'!L13 -> 0 | O13: =+'KPI_VENDEUR 1'!O13 -> 0 | R13: =+'KPI_VENDEUR 1'!R13 -> 0 | U13: =+'KPI_VENDEUR 1'!U13 -> 0 | X13: =+'KPI_VENDEUR 1'!X13 -> 0 | AA13: =+'KPI_VENDEUR 1'!AA13 -> 0 | AD13: =+'KPI_VENDEUR 1'!AD13 -> 0 | AG13: =+'KPI_VENDEUR 1'!AG13 -> 0 | AJ13: =+'KPI_VENDEUR 1'!AJ13 -> 0 | AM13: =+'KPI_VENDEUR 1'!AM13 -> 0
E15: =+E11 -> 0 | F15: =+F11 -> 0 | G15: =F15/E15 -> #DIV/0! | H15: =+H11+E15 -> 0 | I15: =+I11+F15 -> 0 | J15: =I15/H15 -> #DIV/0! | K15: =+K11+H15 -> 0 | L15: =+L11+I15 -> 0 | M15: =L15/K15 -> #DIV/0! | N15: =+N11+K15 -> 0 | O15: =+O11+L15 -> 0 | P15: =O15/N15 -> #DIV/0! | Q15: =+Q11+N15 -> 0 | R15: =+R11+O15 -> 0 | S15: =R15/Q15 -> #DIV/0! | T15: =+T11+Q15 -> 0 | U15: =+U11+R15 -> 0 | V15: =U15/T15 -> #DIV/0! | W15: =+W11+T15 -> 0 | X15: =+X11+U15 -> 0 | Y15: =X15/W15 -> #DIV/0! | Z15: =+Z11+W15 -> 0 | AA15: =+AA11+X15 -> 0 | AB15: =AA15/Z15 -> #DIV/0! | AC15: =+AC11+Z15 -> 0 | AD15: =+AD11+AA15 -> 0 | AE15: =AD15/AC15 -> #DIV/0! | AF15: =+AF11+AC15 -> 0 | AG15: =+AG11+AD15 -> 0 | AH15: =AG15/AF15 -> #DIV/0! | AI15: =+AI11+AF15 -> 0 | AJ15: =+AJ11+AG15 -> 0 | AK15: =AJ15/AI15 -> #DIV/0!

Sheet KPI_VENDEUR 1
A1: VENDEUR 1 | B1: YTD vs B2025 | E1: 45658 | H1: 45689 | K1: 45717 | N1: 45748 | Q1: 45778 | T1: 45809 | W1: 45839 | Z1: 45870 | AC1: 45901 | AF1: 45931 | AI1: 45962 | AL1: 45992
B2: Objectif | C2: Réalisé | D2: % | E2: Objectif | F2: Réalisé | G2: % | H2: Objectif | I2: Réalisé | J2: % | K2: Objectif | L2: Réalisé | M2: % | N2: Objectif | O2: Réalisé | P2: % | Q2: Objectif | R2: Réalisé | S2: % | T2: Objectif | U2: Réalisé | V2: % | W2: Objectif | X2: Réalisé | Y2: % | Z2: Objectif | AA2: Réalisé | AB2: % | AC2: Objectif | AD2: Réalisé | AE2: % | AF2: Objectif | AG2: Réalisé | AH2: % | AI2: Objectif | AJ2: Réalisé | AK2: % | AL2: Objectif | AM2: Réalisé | AN2: %
A3: Nombre de visites clients | B3: =E3+H3+K3+N3+Q3+T3+W3+Z3+AC3+AF3+AI3+AL3 -> 0 | C3: =F3+I3+L3+O3+R3+U3+X3+AA3+AD3+AG3+AJ3+AM3 -> 0 | D3: =C3/B3 -> #DIV/0! | G3: =F3/E3 -> #DIV/0! | J3: =I3/H3 -> #DIV/0! | M3: =L3/K3 -> #DIV/0! | P3: =O3/N3 -> #DIV/0! | S3: =R3/Q3 -> #DIV/0! | V3: =U3/T3 -> #DIV/0! | Y3: =X3/W3 -> #DIV/0! | AB3: =AA3/Z3 -> #DIV/0! | AE3: =AD3/AC3 -> #DIV/0! | AH3: =AG3/AF3 -> #DIV/0! | AK3: =AJ3/AI3 -> #DIV/0! | AN3: =AM3/AL3 -> #DIV/0!
A4: Nombre d'offres commerciales | B4: =E4+H4+K4+N4+Q4+T4+W4+Z4+AC4+AF4+AI4+AL4 -> 0 | C4: =F4+I4+L4+O4+R4+U4+X4+AA4+AD4+AG4+AJ4+AM4 -> 0 | D4: =C4/B4 -> #DIV/0! | G4: =F4/E4 -> #DIV/0! | J4: =I4/H4 -> #DIV/0! | M4: =L4/K4 -> #DIV/0! | P4: =O4/N4 -> #DIV/0! | S4: =R4/Q4 -> #DIV/0! | V4: =U4/T4 -> #DIV/0! | Y4: =X4/W4 -> #DIV/0! | AB4: =AA4/Z4 -> #DIV/0! | AE4: =AD4/AC4 -> #DIV/0! | AH4: =AG4/AF4 -> #DIV/0! | AK4: =AJ4/AI4 -> #DIV/0! | AN4: =AM4/AL4 -> #DIV/0!
A5: Taux de clôture | C5: =F5+I5+L5+O5+R5+U5+X5+AA5+AD5+AG5+AJ5+AM5 -> 0 | D5: =C5/C4 -> #DIV/0! | G5: =F5/F4 -> #DIV/0! | J5: =I5/I4 -> #DIV/0! | M5: =L5/L4 -> #DIV/0! | P5: =O5/O4 -> #DIV/0! | S5: =R5/R4 -> #DIV/0! | V5: =U5/U4 -> #DIV/0! | Y5: =X5/X4 -> #DIV/0! | AB5: =AA5/AA4 -> #DIV/0! | AE5: =AD5/AD4 -> #DIV/0! | AH5: =AG5/AG4 -> #DIV/0! | AK5: =AJ5/AJ4 -> #DIV/0! | AN5: =AM5/AM4 -> #DIV/0!
A6: QTE MANITOU | B6: =E6+H6+K6+N6+Q6+T6+W6+Z6+AC6+AF6+AI6+AL6 -> 0 | C6: =F6+I6+L6+O6+R6+U6+X6+AA6+AD6+AG6+AJ6+AM6 -> 0 | D6: =C6/B6 -> #DIV/0! | G6: =F6/F5 -> #DIV/0! | J6: =I6/I5 -> #DIV/0! | M6: =L6/L5 -> #DIV/0! | P6: =O6/O5 -> #DIV/0! | S6: =R6/R5 -> #DIV/0! | V6: =U6/U5 -> #DIV/0! | Y6: =X6/X5 -> #DIV/0! | AB6: =AA6/AA5 -> #DIV/0! | AE6: =AD6/AD5 -> #DIV/0! | AH6: =AG6/AG5 -> #DIV/0! | AK6: =AJ6/AJ5 -> #DIV/0! | AN6: =AM6/AM5 -> #DIV/0!
A7: QTE KALMAR | B7: =E7+H7+K7+N7+Q7+T7+W7+Z7+AC7+AF7+AI7+AL7 -> 0 | C7: =F7+I7+L7+O7+R7+U7+X7+AA7+AD7+AG7+AJ7+AM7 -> 0 | D7: =C7/B7 -> #DIV/0! | G7: =F7/F6 -> #DIV/0! | J7: =I7/I6 -> #DIV/0! | M7: =L7/L6 -> #DIV/0! | P7: =O7/O6 -> #DIV/0! | S7: =R7/R6 -> #DIV/0! | V7: =U7/U6 -> #DIV/0! | Y7: =X7/X6 -> #DIV/0! | AB7: =AA7/AA6 -> #DIV/0! | AE7: =AD7/AD6 -> #DIV/0! | AH7: =AG7/AG6 -> #DIV/0! | AK7: =AJ7/AJ6 -> #DIV/0! | AN7: =AM7/AM6 -> #DIV/0!
A8: QTE MASSEY FERGUSON | B8: =E8+H8+K8+N8+Q8+T8+W8+Z8+AC8+AF8+AI8+AL8 -> 0 | C8: =F8+I8+L8+O8+R8+U8+X8+AA8+AD8+AG8+AJ8+AM8 -> 0 | D8: =C8/B8 -> #DIV/0! | G8: =F8/F7 -> #DIV/0! | J8: =I8/I7 -> #DIV/0! | M8: =L8/L7 -> #DIV/0! | P8: =O8/O7 -> #DIV/0! | S8: =R8/R7 -> #DIV/0! | V8: =U8/U7 -> #DIV/0! | Y8: =X8/X7 -> #DIV/0! | AB8: =AA8/AA7 -> #DIV/0! | AE8: =AD8/AD7 -> #DIV/0! | AH8: =AG8/AG7 -> #DIV/0! | AK8: =AJ8/AJ7 -> #DIV/0! | AN8: =AM8/AM7 -> #DIV/0!
A9: QTE NARDI | B9: =E9+H9+K9+N9+Q9+T9+W9+Z9+AC9+AF9+AI9+AL9 -> 0 | C9: =F9+I9+L9+O9+R9+U9+X9+AA9+AD9+AG9+AJ9+AM9 -> 0 | D9: =C9/B9 -> #DIV/0! | G9: =F9/F8 -> #DIV/0! | J9: =I9/I8 -> #DIV/0! | M9: =L9/L8 -> #DIV/0! | P9: =O9/O8 -> #DIV/0! | S9: =R9/R8 -> #DIV/0! | V9: =U9/U8 -> #DIV/0! | Y9: =X9/X8 -> #DIV/0! | AB9: =AA9/AA8 -> #DIV/0! | AE9: =AD9/AD8 -> #DIV/0! | AH9: =AG9/AG8 -> #DIV/0! | AK9: =AJ9/AJ8 -> #DIV/0! | AN9: =AM9/AM8 -> #DIV/0!
A10: QTE TOTAL VENTES | B10: =E10+H10+K10+N10+Q10+T10+W10+Z10+AC10+AF10+AI10+AL10 -> 0 | C10: =F10+I10+L10+O10+R10+U10+X10+AA10+AD10+AG10+AJ10+AM10 -> 0 | D10: =C10/B10 -> #DIV/0! | E10: =SUM(E6:E9) -> 0 | F10: =SUM(F6:F9) -> 0 | G10: =F10/E10 -> #DIV/0! | H10: =SUM(H6:H9) -> 0 | I10: =SUM(I6:I9) -> 0 | J10: =I10/H10 -> #DIV/0! | K10: =SUM(K6:K9) -> 0 | L10: =SUM(L6:L9) -> 0 | M10: =L10/K10 -> #DIV/0! | N10: =SUM(N6:N9) -> 0 | O10: =SUM(O6:O9) -> 0 | P10: =O10/N10 -> #DIV/0! | Q10: =SUM(Q6:Q9) -> 0 | R10: =SUM(R6:R9) -> 0 | S10: =R10/Q10 -> #DIV/0! | T10: =SUM(T6:T9) -> 0 | U10: =SUM(U6:U9) -> 0 | V10: =U10/T10 -> #DIV/0! | W10: =SUM(W6:W9) -> 0 | X10: =SUM(X6:X9) -> 0 | Y10: =X10/W10 -> #DIV/0! | Z10: =SUM(Z6:Z9) -> 0 | AA10: =SUM(AA6:AA9) -> 0 | AB10: =AA10/Z10 -> #DIV/0! | AC10: =SUM(AC6:AC9) -> 0 | AD10: =SUM(AD6:AD9) -> 0 | AE10: =AD10/AC10 -> #DIV/0! | AF10: =SUM(AF6:AF9) -> 0 | AG10: =SUM(AG6:AG9) -> 0 | AH10: =AG10/AF10 -> #DIV/0! | AI10: =SUM(AI6:AI9) -> 0 | AJ10: =SUM(AJ6:AJ9) -> 0 | AK10: =AJ10/AI10 -> #DIV/0! | AL10: =SUM(AL6:AL9) -> 0 | AM10: =SUM(AM6:AM9) -> 0 | AN10: =AM10/AL10 -> #DIV/0!
A11: Chiffre d'Affaires (HT) FCFA | B11: =E11+H11+K11+N11+Q11+T11+W11+Z11+AC11+AF11+AI11+AL11 -> 0 | C11: =F11+I11+L11+O11+R11+U11+X11+AA11+AD11+AG11+AJ11+AM11 -> 0 | D11: =C11/B11 -> #DIV/0! | G11: =F11/E11 -> #DIV/0! | J11: =I11/H11 -> #DIV/0! | M11: =L11/K11 -> #DIV/0! | P11: =O11/N11 -> #DIV/0! | S11: =R11/Q11 -> #DIV/0! | V11: =U11/T11 -> #DIV/0! | Y11: =X11/W11 -> #DIV/0! | AB11: =AA11/Z11 -> #DIV/0! | AE11: =AD11/AC11 -> #DIV/0! | AH11: =AG11/AF11 -> #DIV/0! | AK11: =AJ11/AI11 -> #DIV/0! | AN11: =AM11/AL11 -> #DIV/0!
A12: Nombre de Machines en stock | C12: =AVERAGE(AM12,AJ12,AG12,AD12,AA12,X12,U12,R12,O12,L12,I12,F12) -> #DIV/0!
A13: Valeur stock Machines FCFA | C13: =AVERAGE(AM13,AJ13,AG13,AD13,AA13,X13,U13,R13,O13,L13,I13,F13) -> #DIV/0!
E15: =+E11 -> 0 | F15: =+F11 -> 0 | G15: =F15/E15 -> #DIV/0! | H15: =+H11+E15 -> 0 | I15: =+I11+F15 -> 0 | J15: =I15/H15 -> #DIV/0! | K15: =+K11+H15 -> 0 | L15: =+L11+I15 -> 0 | M15: =L15/K15 -> #DIV/0! | N15: =+N11+K15 -> 0 | O15: =+O11+L15 -> 0 | P15: =O15/N15 -> #DIV/0! | Q15: =+Q11+N15 -> 0 | R15: =+R11+O15 -> 0 | S15: =R15/Q15 -> #DIV/0! | T15: =+T11+Q15 -> 0 | U15: =+U11+R15 -> 0 | V15: =U15/T15 -> #DIV/0! | W15: =+W11+T15 -> 0 | X15: =+X11+U15 -> 0 | Y15: =X15/W15 -> #DIV/0! | Z15: =+Z11+W15 -> 0 | AA15: =+AA11+X15 -> 0 | AB15: =AA15/Z15 -> #DIV/0! | AC15: =+AC11+Z15 -> 0 | AD15: =+AD11+AA15 -> 0 | AE15: =AD15/AC15 -> #DIV/0! | AF15: =+AF11+AC15 -> 0 | AG15: =+AG11+AD15 -> 0 | AH15: =AG15/AF15 -> #DIV/0! | AI15: =+AI11+AF15 -> 0 | AJ15: =+AJ11+AG15 -> 0 | AK15: =AJ15/AI15 -> #DIV/0!

Sheet KPI_VENDEUR 2
A1: VENDEUR 2 | B1: YTD vs B2025 | E1: 45658 | H1: 45689 | K1: 45717 | N1: 45748 | Q1: 45778 | T1: 45809 | W1: 45839 | Z1: 45870 | AC1: 45901 | AF1: 45931 | AI1: 45962 | AL1: 45992
B2: Objectif | C2: Réalisé | D2: % | E2: Objectif | F2: Réalisé | G2: % | H2: Objectif | I2: Réalisé | J2: % | K2: Objectif | L2: Réalisé | M2: % | N2: Objectif | O2: Réalisé | P2: % | Q2: Objectif | R2: Réalisé | S2: % | T2: Objectif | U2: Réalisé | V2: % | W2: Objectif | X2: Réalisé | Y2: % | Z2: Objectif | AA2: Réalisé | AB2: % | AC2: Objectif | AD2: Réalisé | AE2: % | AF2: Objectif | AG2: Réalisé | AH2: % | AI2: Objectif | AJ2: Réalisé | AK2: % | AL2: Objectif | AM2: Réalisé | AN2: %
A3: Nombre de visites clients | B3: =E3+H3+K3+N3+Q3+T3+W3+Z3+AC3+AF3+AI3+AL3 -> 0 | C3: =F3+I3+L3+O3+R3+U3+X3+AA3+AD3+AG3+AJ3+AM3 -> 0 | D3: =C3/B3 -> #DIV/0! | G3: =F3/E3 -> #DIV/0! | J3: =I3/H3 -> #DIV/0! | M3: =L3/K3 -> #DIV/0! | P3: =O3/N3 -> #DIV/0! | S3: =R3/Q3 -> #DIV/0! | V3: =U3/T3 -> #DIV/0! | Y3: =X3/W3 -> #DIV/0! | AB3: =AA3/Z3 -> #DIV/0! | AE3: =AD3/AC3 -> #DIV/0! | AH3: =AG3/AF3 -> #DIV/0! | AK3: =AJ3/AI3 -> #DIV/0! | AN3: =AM3/AL3 -> #DIV/0!
A4: Nombre d'offres commerciales | B4: =E4+H4+K4+N4+Q4+T4+W4+Z4+AC4+AF4+AI4+AL4 -> 0 | C4: =F4+I4+L4+O4+R4+U4+X4+AA4+AD4+AG4+AJ4+AM4 -> 0 | D4: =C4/B4 -> #DIV/0! | G4: =F4/E4 -> #DIV/0! | J4: =I4/H4 -> #DIV/0! | M4: =L4/K4 -> #DIV/0! | P4: =O4/N4 -> #DIV/0! | S4: =R4/Q4 -> #DIV/0! | V4: =U4/T4 -> #DIV/0! | Y4: =X4/W4 -> #DIV/0! | AB4: =AA4/Z4 -> #DIV/0! | AE4: =AD4/AC4 -> #DIV/0! | AH4: =AG4/AF4 -> #DIV/0! | AK4: =AJ4/AI4 -> #DIV/0! | AN4: =AM4/AL4 -> #DIV/0!
A5: Taux de clôture | C5: =F5+I5+L5+O5+R5+U5+X5+AA5+AD5+AG5+AJ5+AM5 -> 0 | D5: =C5/C4 -> #DIV/0! | G5: =F5/F4 -> #DIV/0! | J5: =I5/I4 -> #DIV/0! | M5: =L5/L4 -> #DIV/0! | P5: =O5/O4 -> #DIV/0! | S5: =R5/R4 -> #DIV/0! | V5: =U5/U4 -> #DIV/0! | Y5: =X5/X4 -> #DIV/0! | AB5: =AA5/AA4 -> #DIV/0! | AE5: =AD5/AD4 -> #DIV/0! | AH5: =AG5/AG4 -> #DIV/0! | AK5: =AJ5/AJ4 -> #DIV/0! | AN5: =AM5/AM4 -> #DIV/0!
A6: QTE MANITOU | B6: =E6+H6+K6+N6+Q6+T6+W6+Z6+AC6+AF6+AI6+AL6 -> 0 | C6: =F6+I6+L6+O6+R6+U6+X6+AA6+AD6+AG6+AJ6+AM6 -> 0 | D6: =C6/B6 -> #DIV/0! | G6: =F6/F5 -> #DIV/0! | J6: =I6/I5 -> #DIV/0! | M6: =L6/L5 -> #DIV/0! | P6: =O6/O5 -> #DIV/0! | S6: =R6/R5 -> #DIV/0! | V6: =U6/U5 -> #DIV/0! | Y6: =X6/X5 -> #DIV/0! | AB6: =AA6/AA5 -> #DIV/0! | AE6: =AD6/AD5 -> #DIV/0! | AH6: =AG6/AG5 -> #DIV/0! | AK6: =AJ6/AJ5 -> #DIV/0! | AN6: =AM6/AM5 -> #DIV/0!
A7: QTE KALMAR | B7: =E7+H7+K7+N7+Q7+T7+W7+Z7+AC7+AF7+AI7+AL7 -> 0 | C7: =F7+I7+L7+O7+R7+U7+X7+AA7+AD7+AG7+AJ7+AM7 -> 0 | D7: =C7/B7 -> #DIV/0! | G7: =F7/F6 -> #DIV/0! | J7: =I7/I6 -> #DIV/0! | M7: =L7/L6 -> #DIV/0! | P7: =O7/O6 -> #DIV/0! | S7: =R7/R6 -> #DIV/0! | V7: =U7/U6 -> #DIV/0! | Y7: =X7/X6 -> #DIV/0! | AB7: =AA7/AA6 -> #DIV/0! | AE7: =AD7/AD6 -> #DIV/0! | AH7: =AG7/AG6 -> #DIV/0! | AK7: =AJ7/AJ6 -> #DIV/0! | AN7: =AM7/AM6 -> #DIV/0!
A8: QTE MASSEY FERGUSON | B8: =E8+H8+K8+N8+Q8+T8+W8+Z8+AC8+AF8+AI8+AL8 -> 0 | C8: =F8+I8+L8+O8+R8+U8+X8+AA8+AD8+AG8+AJ8+AM8 -> 0 | D8: =C8/B8 -> #DIV/0! | G8: =F8/F7 -> #DIV/0! | J8: =I8/I7 -> #DIV/0! | M8: =L8/L7 -> #DIV/0! | P8: =O8/O7 -> #DIV/0! | S8: =R8/R7 -> #DIV/0! | V8: =U8/U7 -> #DIV/0! | Y8: =X8/X7 -> #DIV/0! | AB8: =AA8/AA7 -> #DIV/0! | AE8: =AD8/AD7 -> #DIV/0! | AH8: =AG8/AG7 -> #DIV/0! | AK8: =AJ8/AJ7 -> #DIV/0! | AN8: =AM8/AM7 -> #DIV/0!
A9: QTE NARDI | B9: =E9+H9+K9+N9+Q9+T9+W9+Z9+AC9+AF9+AI9+AL9 -> 0 | C9: =F9+I9+L9+O9+R9+U9+X9+AA9+AD9+AG9+AJ9+AM9 -> 0 | D9: =C9/B9 -> #DIV/0! | G9: =F9/F8 -> #DIV/0! | J9: =I9/I8 -> #DIV/0! | M9: =L9/L8 -> #DIV/0! | P9: =O9/O8 -> #DIV/0! | S9: =R9/R8 -> #DIV/0! | V9: =U9/U8 -> #DIV/0! | Y9: =X9/X8 -> #DIV/0! | AB9: =AA9/AA8 -> #DIV/0! | AE9: =AD9/AD8 -> #DIV/0! | AH9: =AG9/AG8 -> #DIV/0! | AK9: =AJ9/AJ8 -> #DIV/0! | AN9: =AM9/AM8 -> #DIV/0!
A10: QTE TOTAL VENTES | B10: =E10+H10+K10+N10+Q10+T10+W10+Z10+AC10+AF10+AI10+AL10 -> 0 | C10: =F10+I10+L10+O10+R10+U10+X10+AA10+AD10+AG10+AJ10+AM10 -> 0 | D10: =C10/B10 -> #DIV/0! | E10: =SUM(E6:E9) -> 0 | F10: =SUM(F6:F9) -> 0 | G10: =F10/E10 -> #DIV/0! | H10: =SUM(H6:H9) -> 0 | I10: =SUM(I6:I9) -> 0 | J10: =I10/H10 -> #DIV/0! | K10: =SUM(K6:K9) -> 0 | L10: =SUM(L6:L9) -> 0 | M10: =L10/K10 -> #DIV/0! | N10: =SUM(N6:N9) -> 0 | O10: =SUM(O6:O9) -> 0 | P10: =O10/N10 -> #DIV/0! | Q10: =SUM(Q6:Q9) -> 0 | R10: =SUM(R6:R9) -> 0 | S10: =R10/Q10 -> #DIV/0! | T10: =SUM(T6:T9) -> 0 | U10: =SUM(U6:U9) -> 0 | V10: =U10/T10 -> #DIV/0! | W10: =SUM(W6:W9) -> 0 | X10: =SUM(X6:X9) -> 0 | Y10: =X10/W10 -> #DIV/0! | Z10: =SUM(Z6:Z9) -> 0 | AA10: =SUM(AA6:AA9) -> 0 | AB10: =AA10/Z10 -> #DIV/0! | AC10: =SUM(AC6:AC9) -> 0 | AD10: =SUM(AD6:AD9) -> 0 | AE10: =AD10/AC10 -> #DIV/0! | AF10: =SUM(AF6:AF9) -> 0 | AG10: =SUM(AG6:AG9) -> 0 | AH10: =AG10/AF10 -> #DIV/0! | AI10: =SUM(AI6:AI9) -> 0 | AJ10: =SUM(AJ6:AJ9) -> 0 | AK10: =AJ10/AI10 -> #DIV/0! | AL10: =SUM(AL6:AL9) -> 0 | AM10: =SUM(AM6:AM9) -> 0 | AN10: =AM10/AL10 -> #DIV/0!
A11: Chiffre d'Affaires (HT) FCFA | B11: =E11+H11+K11+N11+Q11+T11+W11+Z11+AC11+AF11+AI11+AL11 -> 0 | C11: =F11+I11+L11+O11+R11+U11+X11+AA11+AD11+AG11+AJ11+AM11 -> 0 | D11: =C11/B11 -> #DIV/0! | G11: =F11/E11 -> #DIV/0! | J11: =I11/H11 -> #DIV/0! | M11: =L11/K11 -> #DIV/0! | P11: =O11/N11 -> #DIV/0! | S11: =R11/Q11 -> #DIV/0! | V11: =U11/T11 -> #DIV/0! | Y11: =X11/W11 -> #DIV/0! | AB11: =AA11/Z11 -> #DIV/0! | AE11: =AD11/AC11 -> #DIV/0! | AH11: =AG11/AF11 -> #DIV/0! | AK11: =AJ11/AI11 -> #DIV/0! | AN11: =AM11/AL11 -> #DIV/0!
E13: =+E11 -> 0 | F13: =+F11 -> 0 | G13: =F13/E13 -> #DIV/0! | H13: =+H11+E13 -> 0 | I13: =+I11+F13 -> 0 | J13: =I13/H13 -> #DIV/0! | K13: =+K11+H13 -> 0 | L13: =+L11+I13 -> 0 | M13: =L13/K13 -> #DIV/0! | N13: =+N11+K13 -> 0 | O13: =+O11+L13 -> 0 | P13: =O13/N13 -> #DIV/0! | Q13: =+Q11+N13 -> 0 | R13: =+R11+O13 -> 0 | S13: =R13/Q13 -> #DIV/0! | T13: =+T11+Q13 -> 0 | U13: =+U11+R13 -> 0 | V13: =U13/T13 -> #DIV/0! | W13: =+W11+T13 -> 0 | X13: =+X11+U13 -> 0 | Y13: =X13/W13 -> #DIV/0! | Z13: =+Z11+W13 -> 0 | AA13: =+AA11+X13 -> 0 | AB13: =AA13/Z13 -> #DIV/0! | AC13: =+AC11+Z13 -> 0 | AD13: =+AD11+AA13 -> 0 | AE13: =AD13/AC13 -> #DIV/0! | AF13: =+AF11+AC13 -> 0 | AG13: =+AG11+AD13 -> 0 | AH13: =AG13/AF13 -> #DIV/0! | AI13: =+AI11+AF13 -> 0 | AJ13: =+AJ11+AG13 -> 0 | AK13: =AJ13/AI13 -> #DIV/0!

Sheet KPI_VENDEUR 3
A1: VENDEUR 3 | B1: YTD vs B2025 | E1: 45658 | H1: 45689 | K1: 45717 | N1: 45748 | Q1: 45778 | T1: 45809 | W1: 45839 | Z1: 45870 | AC1: 45901 | AF1: 45931 | AI1: 45962 | AL1: 45992
B2: Objectif | C2: Réalisé | D2: % | E2: Objectif | F2: Réalisé | G2: % | H2: Objectif | I2: Réalisé | J2: % | K2: Objectif | L2: Réalisé | M2: % | N2: Objectif | O2: Réalisé | P2: % | Q2: Objectif | R2: Réalisé | S2: % | T2: Objectif | U2: Réalisé | V2: % | W2: Objectif | X2: Réalisé | Y2: % | Z2: Objectif | AA2: Réalisé | AB2: % | AC2: Objectif | AD2: Réalisé | AE2: % | AF2: Objectif | AG2: Réalisé | AH2: % | AI2: Objectif | AJ2: Réalisé | AK2: % | AL2: Objectif | AM2: Réalisé | AN2: %
A3: Nombre de visites clients | B3: =E3+H3+K3+N3+Q3+T3+W3+Z3+AC3+AF3+AI3+AL3 -> 0 | C3: =F3+I3+L3+O3+R3+U3+X3+AA3+AD3+AG3+AJ3+AM3 -> 0 | D3: =C3/B3 -> #DIV/0! | G3: =F3/E3 -> #DIV/0! | J3: =I3/H3 -> #DIV/0! | M3: =L3/K3 -> #DIV/0! | P3: =O3/N3 -> #DIV/0! | S3: =R3/Q3 -> #DIV/0! | V3: =U3/T3 -> #DIV/0! | Y3: =X3/W3 -> #DIV/0! | AB3: =AA3/Z3 -> #DIV/0! | AE3: =AD3/AC3 -> #DIV/0! | AH3: =AG3/AF3 -> #DIV/0! | AK3: =AJ3/AI3 -> #DIV/0! | AN3: =AM3/AL3 -> #DIV/0!
A4: Nombre d'offres commerciales | B4: =E4+H4+K4+N4+Q4+T4+W4+Z4+AC4+AF4+AI4+AL4 -> 0 | C4: =F4+I4+L4+O4+R4+U4+X4+AA4+AD4+AG4+AJ4+AM4 -> 0 | D4: =C4/B4 -> #DIV/0! | G4: =F4/E4 -> #DIV/0! | J4: =I4/H4 -> #DIV/0! | M4: =L4/K4 -> #DIV/0! | P4: =O4/N4 -> #DIV/0! | S4: =R4/Q4 -> #DIV/0! | V4: =U4/T4 -> #DIV/0! | Y4: =X4/W4 -> #DIV/0! | AB4: =AA4/Z4 -> #DIV/0! | AE4: =AD4/AC4 -> #DIV/0! | AH4: =AG4/AF4 -> #DIV/0! | AK4: =AJ4/AI4 -> #DIV/0! | AN4: =AM4/AL4 -> #DIV/0!
A5: Taux de clôture | C5: =F5+I5+L5+O5+R5+U5+X5+AA5+AD5+AG5+AJ5+AM5 -> 0 | D5: =C5/C4 -> #DIV/0! | G5: =F5/F4 -> #DIV/0! | J5: =I5/I4 -> #DIV/0! | M5: =L5/L4 -> #DIV/0! | P5: =O5/O4 -> #DIV/0! | S5: =R5/R4 -> #DIV/0! | V5: =U5/U4 -> #DIV/0! | Y5: =X5/X4 -> #DIV/0! | AB5: =AA5/AA4 -> #DIV/0! | AE5: =AD5/AD4 -> #DIV/0! | AH5: =AG5/AG4 -> #DIV/0! | AK5: =AJ5/AJ4 -> #DIV/0! | AN5: =AM5/AM4 -> #DIV/0!
A6: QTE MANITOU | B6: =E6+H6+K6+N6+Q6+T6+W6+Z6+AC6+AF6+AI6+AL6 -> 0 | C6: =F6+I6+L6+O6+R6+U6+X6+AA6+AD6+AG6+AJ6+AM6 -> 0 | D6: =C6/B6 -> #DIV/0! | G6: =F6/F5 -> #DIV/0! | J6: =I6/I5 -> #DIV/0! | M6: =L6/L5 -> #DIV/0! | P6: =O6/O5 -> #DIV/0! | S6: =R6/R5 -> #DIV/0! | V6: =U6/U5 -> #DIV/0! | Y6: =X6/X5 -> #DIV/0! | AB6: =AA6/AA5 -> #DIV/0! | AE6: =AD6/AD5 -> #DIV/0! | AH6: =AG6/AG5 -> #DIV/0! | AK6: =AJ6/AJ5 -> #DIV/0! | AN6: =AM6/AM5 -> #DIV/0!
A7: QTE KALMAR | B7: =E7+H7+K7+N7+Q7+T7+W7+Z7+AC7+AF7+AI7+AL7 -> 0 | C7: =F7+I7+L7+O7+R7+U7+X7+AA7+AD7+AG7+AJ7+AM7 -> 0 | D7: =C7/B7 -> #DIV/0! | G7: =F7/F6 -> #DIV/0! | J7: =I7/I6 -> #DIV/0! | M7: =L7/L6 -> #DIV/0! | P7: =O7/O6 -> #DIV/0! | S7: =R7/R6 -> #DIV/0! | V7: =U7/U6 -> #DIV/0! | Y7: =X7/X6 -> #DIV/0! | AB7: =AA7/AA6 -> #DIV/0! | AE7: =AD7/AD6 -> #DIV/0! | AH7: =AG7/AG6 -> #DIV/0! | AK7: =AJ7/AJ6 -> #DIV/0! | AN7: =AM7/AM6 -> #DIV/0!
A8: QTE MASSEY FERGUSON | B8: =E8+H8+K8+N8+Q8+T8+W8+Z8+AC8+AF8+AI8+AL8 -> 0 | C8: =F8+I8+L8+O8+R8+U8+X8+AA8+AD8+AG8+AJ8+AM8 -> 0 | D8: =C8/B8 -> #DIV/0! | G8: =F8/F7 -> #DIV/0! | J8: =I8/I7 -> #DIV/0! | M8: =L8/L7 -> #DIV/0! | P8: =O8/O7 -> #DIV/0! | S8: =R8/R7 -> #DIV/0! | V8: =U8/U7 -> #DIV/0! | Y8: =X8/X7 -> #DIV/0! | AB8: =AA8/AA7 -> #DIV/0! | AE8: =AD8/AD7 -> #DIV/0! | AH8: =AG8/AG7 -> #DIV/0! | AK8: =AJ8/AJ7 -> #DIV/0! | AN8: =AM8/AM7 -> #DIV/0!
A9: QTE NARDI | B9: =E9+H9+K9+N9+Q9+T9+W9+Z9+AC9+AF9+AI9+AL9 -> 0 | C9: =F9+I9+L9+O9+R9+U9+X9+AA9+AD9+AG9+AJ9+AM9 -> 0 | D9: =C9/B9 -> #DIV/0! | G9: =F9/F8 -> #DIV/0! | J9: =I9/I8 -> #DIV/0! | M9: =L9/L8 -> #DIV/0! | P9: =O9/O8 -> #DIV/0! | S9: =R9/R8 -> #DIV/0! | V9: =U9/U8 -> #DIV/0! | Y9: =X9/X8 -> #DIV/0! | AB9: =AA9/AA8 -> #DIV/0! | AE9: =AD9/AD8 -> #DIV/0! | AH9: =AG9/AG8 -> #DIV/0! | AK9: =AJ9/AJ8 -> #DIV/0! | AN9: =AM9/AM8 -> #DIV/0!
A10: QTE TOTAL VENTES | B10: =E10+H10+K10+N10+Q10+T10+W10+Z10+AC10+AF10+AI10+AL10 -> 0 | C10: =F10+I10+L10+O10+R10+U10+X10+AA10+AD10+AG10+AJ10+AM10 -> 0 | D10: =C10/B10 -> #DIV/0! | E10: =SUM(E6:E9) -> 0 | F10: =SUM(F6:F9) -> 0 | G10: =F10/E10 -> #DIV/0! | H10: =SUM(H6:H9) -> 0 | I10: =SUM(I6:I9) -> 0 | J10: =I10/H10 -> #DIV/0! | K10: =SUM(K6:K9) -> 0 | L10: =SUM(L6:L9) -> 0 | M10: =L10/K10 -> #DIV/0! | N10: =SUM(N6:N9) -> 0 | O10: =SUM(O6:O9) -> 0 | P10: =O10/N10 -> #DIV/0! | Q10: =SUM(Q6:Q9) -> 0 | R10: =SUM(R6:R9) -> 0 | S10: =R10/Q10 -> #DIV/0! | T10: =SUM(T6:T9) -> 0 | U10: =SUM(U6:U9) -> 0 | V10: =U10/T10 -> #DIV/0! | W10: =SUM(W6:W9) -> 0 | X10: =SUM(X6:X9) -> 0 | Y10: =X10/W10 -> #DIV/0! | Z10: =SUM(Z6:Z9) -> 0 | AA10: =SUM(AA6:AA9) -> 0 | AB10: =AA10/Z10 -> #DIV/0! | AC10: =SUM(AC6:AC9) -> 0 | AD10: =SUM(AD6:AD9) -> 0 | AE10: =AD10/AC10 -> #DIV/0! | AF10: =SUM(AF6:AF9) -> 0 | AG10: =SUM(AG6:AG9) -> 0 | AH10: =AG10/AF10 -> #DIV/0! | AI10: =SUM(AI6:AI9) -> 0 | AJ10: =SUM(AJ6:AJ9) -> 0 | AK10: =AJ10/AI10 -> #DIV/0! | AL10: =SUM(AL6:AL9) -> 0 | AM10: =SUM(AM6:AM9) -> 0 | AN10: =AM10/AL10 -> #DIV/0!
A11: Chiffre d'Affaires (HT) FCFA | B11: =E11+H11+K11+N11+Q11+T11+W11+Z11+AC11+AF11+AI11+AL11 -> 0 | C11: =F11+I11+L11+O11+R11+U11+X11+AA11+AD11+AG11+AJ11+AM11 -> 0 | D11: =C11/B11 -> #DIV/0! | G11: =F11/E11 -> #DIV/0! | J11: =I11/H11 -> #DIV/0! | M11: =L11/K11 -> #DIV/0! | P11: =O11/N11 -> #DIV/0! | S11: =R11/Q11 -> #DIV/0! | V11: =U11/T11 -> #DIV/0! | Y11: =X11/W11 -> #DIV/0! | AB11: =AA11/Z11 -> #DIV/0! | AE11: =AD11/AC11 -> #DIV/0! | AH11: =AG11/AF11 -> #DIV/0! | AK11: =AJ11/AI11 -> #DIV/0! | AN11: =AM11/AL11 -> #DIV/0!
E13: =+E11 -> 0 | F13: =+F11 -> 0 | G13: =F13/E13 -> #DIV/0! | H13: =+H11+E13 -> 0 | I13: =+I11+F13 -> 0 | J13: =I13/H13 -> #DIV/0! | K13: =+K11+H13 -> 0 | L13: =+L11+I13 -> 0 | M13: =L13/K13 -> #DIV/0! | N13: =+N11+K13 -> 0 | O13: =+O11+L13 -> 0 | P13: =O13/N13 -> #DIV/0! | Q13: =+Q11+N13 -> 0 | R13: =+R11+O13 -> 0 | S13: =R13/Q13 -> #DIV/0! | T13: =+T11+Q13 -> 0 | U13: =+U11+R13 -> 0 | V13: =U13/T13 -> #DIV/0! | W13: =+W11+T13 -> 0 | X13: =+X11+U13 -> 0 | Y13: =X13/W13 -> #DIV/0! | Z13: =+Z11+W13 -> 0 | AA13: =+AA11+X13 -> 0 | AB13: =AA13/Z13 -> #DIV/0! | AC13: =+AC11+Z13 -> 0 | AD13: =+AD11+AA13 -> 0 | AE13: =AD13/AC13 -> #DIV/0! | AF13: =+AF11+AC13 -> 0 | AG13: =+AG11+AD13 -> 0 | AH13: =AG13/AF13 -> #DIV/0! | AI13: =+AI11+AF13 -> 0 | AJ13: =+AJ11+AG13 -> 0 | AK13: =AJ13/AI13 -> #DIV/0!

Sheet KPI_VENDEUR 4
A1: VENDEUR 4 | B1: YTD vs B2025 | E1: 45658 | H1: 45689 | K1: 45717 | N1: 45748 | Q1: 45778 | T1: 45809 | W1: 45839 | Z1: 45870 | AC1: 45901 | AF1: 45931 | AI1: 45962 | AL1: 45992
B2: Objectif | C2: Réalisé | D2: % | E2: Objectif | F2: Réalisé | G2: % | H2: Objectif | I2: Réalisé | J2: % | K2: Objectif | L2: Réalisé | M2: % | N2: Objectif | O2: Réalisé | P2: % | Q2: Objectif | R2: Réalisé | S2: % | T2: Objectif | U2: Réalisé | V2: % | W2: Objectif | X2: Réalisé | Y2: % | Z2: Objectif | AA2: Réalisé | AB2: % | AC2: Objectif | AD2: Réalisé | AE2: % | AF2: Objectif | AG2: Réalisé | AH2: % | AI2: Objectif | AJ2: Réalisé | AK2: % | AL2: Objectif | AM2: Réalisé | AN2: %
A3: Nombre de visites clients | B3: =E3+H3+K3+N3+Q3+T3+W3+Z3+AC3+AF3+AI3+AL3 -> 0 | C3: =F3+I3+L3+O3+R3+U3+X3+AA3+AD3+AG3+AJ3+AM3 -> 0 | D3: =C3/B3 -> #DIV/0! | G3: =F3/E3 -> #DIV/0! | J3: =I3/H3 -> #DIV/0! | M3: =L3/K3 -> #DIV/0! | P3: =O3/N3 -> #DIV/0! | S3: =R3/Q3 -> #DIV/0! | V3: =U3/T3 -> #DIV/0! | Y3: =X3/W3 -> #DIV/0! | AB3: =AA3/Z3 -> #DIV/0! | AE3: =AD3/AC3 -> #DIV/0! | AH3: =AG3/AF3 -> #DIV/0! | AK3: =AJ3/AI3 -> #DIV/0! | AN3: =AM3/AL3 -> #DIV/0!
A4: Nombre d'offres commerciales | B4: =E4+H4+K4+N4+Q4+T4+W4+Z4+AC4+AF4+AI4+AL4 -> 0 | C4: =F4+I4+L4+O4+R4+U4+X4+AA4+AD4+AG4+AJ4+AM4 -> 0 | D4: =C4/B4 -> #DIV/0! | G4: =F4/E4 -> #DIV/0! | J4: =I4/H4 -> #DIV/0! | M4: =L4/K4 -> #DIV/0! | P4: =O4/N4 -> #DIV/0! | S4: =R4/Q4 -> #DIV/0! | V4: =U4/T4 -> #DIV/0! | Y4: =X4/W4 -> #DIV/0! | AB4: =AA4/Z4 -> #DIV/0! | AE4: =AD4/AC4 -> #DIV/0! | AH4: =AG4/AF4 -> #DIV/0! | AK4: =AJ4/AI4 -> #DIV/0! | AN4: =AM4/AL4 -> #DIV/0!
A5: Taux de clôture | C5: =F5+I5+L5+O5+R5+U5+X5+AA5+AD5+AG5+AJ5+AM5 -> 0 | D5: =C5/C4 -> #DIV/0! | G5: =F5/F4 -> #DIV/0! | J5: =I5/I4 -> #DIV/0! | M5: =L5/L4 -> #DIV/0! | P5: =O5/O4 -> #DIV/0! | S5: =R5/R4 -> #DIV/0! | V5: =U5/U4 -> #DIV/0! | Y5: =X5/X4 -> #DIV/0! | AB5: =AA5/AA4 -> #DIV/0! | AE5: =AD5/AD4 -> #DIV/0! | AH5: =AG5/AG4 -> #DIV/0! | AK5: =AJ5/AJ4 -> #DIV/0! | AN5: =AM5/AM4 -> #DIV/0!
A6: QTE MANITOU | B6: =E6+H6+K6+N6+Q6+T6+W6+Z6+AC6+AF6+AI6+AL6 -> 0 | C6: =F6+I6+L6+O6+R6+U6+X6+AA6+AD6+AG6+AJ6+AM6 -> 0 | D6: =C6/B6 -> #DIV/0! | G6: =F6/F5 -> #DIV/0! | J6: =I6/I5 -> #DIV/0! | M6: =L6/L5 -> #DIV/0! | P6: =O6/O5 -> #DIV/0! | S6: =R6/R5 -> #DIV/0! | V6: =U6/U5 -> #DIV/0! | Y6: =X6/X5 -> #DIV/0! | AB6: =AA6/AA5 -> #DIV/0! | AE6: =AD6/AD5 -> #DIV/0! | AH6: =AG6/AG5 -> #DIV/0! | AK6: =AJ6/AJ5 -> #DIV/0! | AN6: =AM6/AM5 -> #DIV/0!
A7: QTE KALMAR | B7: =E7+H7+K7+N7+Q7+T7+W7+Z7+AC7+AF7+AI7+AL7 -> 0 | C7: =F7+I7+L7+O7+R7+U7+X7+AA7+AD7+AG7+AJ7+AM7 -> 0 | D7: =C7/B7 -> #DIV/0! | G7: =F7/F6 -> #DIV/0! | J7: =I7/I6 -> #DIV/0! | M7: =L7/L6 -> #DIV/0! | P7: =O7/O6 -> #DIV/0! | S7: =R7/R6 -> #DIV/0! | V7: =U7/U6 -> #DIV/0! | Y7: =X7/X6 -> #DIV/0! | AB7: =AA7/AA6 -> #DIV/0! | AE7: =AD7/AD6 -> #DIV/0! | AH7: =AG7/AG6 -> #DIV/0! | AK7: =AJ7/AJ6 -> #DIV/0! | AN7: =AM7/AM6 -> #DIV/0!
A8: QTE MASSEY FERGUSON | B8: =E8+H8+K8+N8+Q8+T8+W8+Z8+AC8+AF8+AI8+AL8 -> 0 | C8: =F8+I8+L8+O8+R8+U8+X8+AA8+AD8+AG8+AJ8+AM8 -> 0 | D8: =C8/B8 -> #DIV/0! | G8: =F8/F7 -> #DIV/0! | J8: =I8/I7 -> #DIV/0! | M8: =L8/L7 -> #DIV/0! | P8: =O8/O7 -> #DIV/0! | S8: =R8/R7 -> #DIV/0! | V8: =U8/U7 -> #DIV/0! | Y8: =X8/X7 -> #DIV/0! | AB8: =AA8/AA7 -> #DIV/0! | AE8: =AD8/AD7 -> #DIV/0! | AH8: =AG8/AG7 -> #DIV/0! | AK8: =AJ8/AJ7 -> #DIV/0! | AN8: =AM8/AM7 -> #DIV/0!
A9: QTE NARDI | B9: =E9+H9+K9+N9+Q9+T9+W9+Z9+AC9+AF9+AI9+AL9 -> 0 | C9: =F9+I9+L9+O9+R9+U9+X9+AA9+AD9+AG9+AJ9+AM9 -> 0 | D9: =C9/B9 -> #DIV/0! | G9: =F9/F8 -> #DIV/0! | J9: =I9/I8 -> #DIV/0! | M9: =L9/L8 -> #DIV/0! | P9: =O9/O8 -> #DIV/0! | S9: =R9/R8 -> #DIV/0! | V9: =U9/U8 -> #DIV/0! | Y9: =X9/X8 -> #DIV/0! | AB9: =AA9/AA8 -> #DIV/0! | AE9: =AD9/AD8 -> #DIV/0! | AH9: =AG9/AG8 -> #DIV/0! | AK9: =AJ9/AJ8 -> #DIV/0! | AN9: =AM9/AM8 -> #DIV/0!
A10: QTE TOTAL VENTES | B10: =E10+H10+K10+N10+Q10+T10+W10+Z10+AC10+AF10+AI10+AL10 -> 0 | C10: =F10+I10+L10+O10+R10+U10+X10+AA10+AD10+AG10+AJ10+AM10 -> 0 | D10: =C10/B10 -> #DIV/0! | E10: =SUM(E6:E9) -> 0 | F10: =SUM(F6:F9) -> 0 | G10: =F10/E10 -> #DIV/0! | H10: =SUM(H6:H9) -> 0 | I10: =SUM(I6:I9) -> 0 | J10: =I10/H10 -> #DIV/0! | K10: =SUM(K6:K9) -> 0 | L10: =SUM(L6:L9) -> 0 | M10: =L10/K10 -> #DIV/0! | N10: =SUM(N6:N9) -> 0 | O10: =SUM(O6:O9) -> 0 | P10: =O10/N10 -> #DIV/0! | Q10: =SUM(Q6:Q9) -> 0 | R10: =SUM(R6:R9) -> 0 | S10: =R10/Q10 -> #DIV/0! | T10: =SUM(T6:T9) -> 0 | U10: =SUM(U6:U9) -> 0 | V10: =U10/T10 -> #DIV/0! | W10: =SUM(W6:W9) -> 0 | X10: =SUM(X6:X9) -> 0 | Y10: =X10/W10 -> #DIV/0! | Z10: =SUM(Z6:Z9) -> 0 | AA10: =SUM(AA6:AA9) -> 0 | AB10: =AA10/Z10 -> #DIV/0! | AC10: =SUM(AC6:AC9) -> 0 | AD10: =SUM(AD6:AD9) -> 0 | AE10: =AD10/AC10 -> #DIV/0! | AF10: =SUM(AF6:AF9) -> 0 | AG10: =SUM(AG6:AG9) -> 0 | AH10: =AG10/AF10 -> #DIV/0! | AI10: =SUM(AI6:AI9) -> 0 | AJ10: =SUM(AJ6:AJ9) -> 0 | AK10: =AJ10/AI10 -> #DIV/0! | AL10: =SUM(AL6:AL9) -> 0 | AM10: =SUM(AM6:AM9) -> 0 | AN10: =AM10/AL10 -> #DIV/0!
A11: Chiffre d'Affaires (HT) FCFA | B11: =E11+H11+K11+N11+Q11+T11+W11+Z11+AC11+AF11+AI11+AL11 -> 0 | C11: =F11+I11+L11+O11+R11+U11+X11+AA11+AD11+AG11+AJ11+AM11 -> 0 | D11: =C11/B11 -> #DIV/0! | G11: =F11/E11 -> #DIV/0! | J11: =I11/H11 -> #DIV/0! | M11: =L11/K11 -> #DIV/0! | P11: =O11/N11 -> #DIV/0! | S11: =R11/Q11 -> #DIV/0! | V11: =U11/T11 -> #DIV/0! | Y11: =X11/W11 -> #DIV/0! | AB11: =AA11/Z11 -> #DIV/0! | AE11: =AD11/AC11 -> #DIV/0! | AH11: =AG11/AF11 -> #DIV/0! | AK11: =AJ11/AI11 -> #DIV/0! | AN11: =AM11/AL11 -> #DIV/0!
